<?xml version="1.0" ?>
<!-- =================================================================================== -->
<!-- |    This document was autogenerated by xacro from mir.urdf.xacro                 | -->
<!-- |    EDITING THIS FILE BY HAND IS NOT RECOMMENDED                                 | -->
<!-- =================================================================================== -->
<robot name="mir_250">
  <!--
    Base UR robot series xacro macro.

    NOTE this is NOT a URDF. It cannot directly be loaded by consumers
    expecting a flattened '.urdf' file. See the top-level '.xacro' for that
    (but note that .xacro must still be processed by the xacro command).

    This file models the base kinematic chain of a UR robot, which then gets
    parameterised by various configuration files to convert it into a UR3(e),
    UR5(e), UR10(e) or UR16e.

    NOTE the default kinematic parameters (i.e., link lengths, frame locations,
    offsets, etc) do not correspond to any particular robot. They are defaults
    only. There WILL be non-zero offsets between the Forward Kinematics results
    in TF (i.e., robot_state_publisher) and the values reported by the Teach
    Pendant.

    For accurate (and robot-specific) transforms, the 'kinematics_parameters_file'
    parameter MUST point to a .yaml file containing the appropriate values for
    the targeted robot.

    If using the UniversalRobots/Universal_Robots_ROS_Driver, follow the steps
    described in the readme of that repository to extract the kinematic
    calibration from the controller and generate the required .yaml file.

    Main author of the migration to yaml configs Ludovic Delval.

    Contributors to previous versions (in no particular order)

     - Denis Stogl
     - Lovro Ivanov
     - Felix Messmer
     - Kelsey Hawkins
     - Wim Meeussen
     - Shaun Edwards
     - Nadia Hammoudeh Garcia
     - Dave Hershberger
     - G. vd. Hoorn
     - Philip Long
     - Dave Coleman
     - Miguel Prada
     - Mathias Luedtke
     - Marcel Schnirring
     - Felix von Drigalski
     - Felix Exner
     - Jimmy Da Silva
     - Ajit Krisshna N L
     - Muhammad Asif Rana
  -->
  <!--
    NOTE the macro defined in this file is NOT part of the public API of this
          package. Users CANNOT rely on this file being available, or stored in
          this location. Nor can they rely on the existence of the macro.
  -->
  <material name="aluminum">
    <color rgba="0.5 0.5 0.5 1"/>
  </material>
  <material name="plastic">
    <color rgba="0.1 0.1 0.1 1"/>
  </material>
  <link name="base_footprint"/>
  <joint name="base_joint" type="fixed">
    <parent link="base_footprint"/>
    <child link="base_link"/>
    <origin rpy="0 0 0" xyz="0 0 0"/>
  </joint>
  <link name="base_link">
    <inertial>
      <mass value="97.0"/>
      <origin rpy="0 0 0" xyz="-0.054485000000000006 0.0 0.15"/>
      <inertia ixx="1.050832913" ixy="0.0" ixz="0.0" iyy="2.344165729" iyz="0.0" izz="2.7483322339999994"/>
    </inertial>
    <visual>
      <origin rpy="0 0 0" xyz="-0.004485 0 0"/>
      <geometry>
        <!--mesh filename="package://mir_description/meshes/visual/mir_100_base.stl" /-->
        <mesh filename="package://mir_description/meshes/visual/mir_250_base.stl"/>
      </geometry>
      <!--xacro:insert_block name="material_white" /-->
      <material name="light_grey">
        <color rgba="0.6 0.6 0.6 1"/>
      </material>
    </visual>
    <collision>
      <origin rpy="0 0 0" xyz="-0.004485 0 0"/>
      <geometry>
        <!--mesh filename="package://mir_description/meshes/collision/mir_100_base.stl" /-->
        <mesh filename="package://mir_description/meshes/collision/mir_250_base.stl"/>
      </geometry>
    </collision>
  </link>
  <gazebo reference="base_link">
    <!--material>Gazebo/White</material-->
    <material>Gazebo/Grey</material>
  </gazebo>
  <!-- IMU -->
  <joint name="base_link_to_imu_joint" type="fixed">
    <parent link="base_link"/>
    <child link="imu_link"/>
    <origin rpy="0 0 0" xyz="0.0 0.0 0.25"/>
    <!-- same as real MiR -->
  </joint>
  <link name="imu_link"/>
  <gazebo reference="imu_link">
    <gravity>true</gravity>
    <sensor name="imu_sensor" type="imu">
      <always_on>true</always_on>
      <update_rate>50.0</update_rate>
      <visualize>true</visualize>
      <imu>
        <angular_velocity>
          <x>
            <noise type="gaussian">
              <mean>0.0</mean>
              <stddev>0.00017</stddev>
              <bias_mean>0.0000075</bias_mean>
              <bias_stddev>0.0000008</bias_stddev>
            </noise>
          </x>
          <y>
            <noise type="gaussian">
              <mean>0.0</mean>
              <stddev>0.00017</stddev>
              <bias_mean>0.0000075</bias_mean>
              <bias_stddev>0.0000008</bias_stddev>
            </noise>
          </y>
          <z>
            <noise type="gaussian">
              <mean>0.0</mean>
              <stddev>0.00017</stddev>
              <bias_mean>0.0000075</bias_mean>
              <bias_stddev>0.0000008</bias_stddev>
            </noise>
          </z>
        </angular_velocity>
        <linear_acceleration>
          <x>
            <noise type="gaussian">
              <mean>0.0</mean>
              <stddev>0.00017</stddev>
              <bias_mean>0.1</bias_mean>
              <bias_stddev>0.001</bias_stddev>
            </noise>
          </x>
          <y>
            <noise type="gaussian">
              <mean>0.0</mean>
              <stddev>0.00017</stddev>
              <bias_mean>0.1</bias_mean>
              <bias_stddev>0.001</bias_stddev>
            </noise>
          </y>
          <z>
            <noise type="gaussian">
              <mean>0.0</mean>
              <stddev>0.00017</stddev>
              <bias_mean>0.1</bias_mean>
              <bias_stddev>0.001</bias_stddev>
            </noise>
          </z>
        </linear_acceleration>
      </imu>
      <plugin filename="libgazebo_ros_imu_sensor.so" name="imu_plugin">
        <initial_orientation_as_reference>false</initial_orientation_as_reference>
        <ros>
          <namespace>imu_data</namespace>
          <remapping>~/out:=data</remapping>
          <frame_name>imu_frame</frame_name>
          <!-- from real MiR -->
        </ros>
      </plugin>
    </sensor>
  </gazebo>
  <!-- Create an alias for imu_link. This is necessary because the real MiR's
         TF has imu_link, but the imu_data topic is published in the imu_frame
         frame. -->
  <joint name="imu_link_to_imu_frame_joint" type="fixed">
    <parent link="imu_link"/>
    <child link="imu_frame"/>
    <origin rpy="0 0 0" xyz="0 0 0"/>
  </joint>
  <link name="imu_frame"/>
  <!-- Laser scanners -->
  <!-- virtual link for merged laserscan-->
  <joint name="base_link_to_virtual_laser_joint" type="fixed">
    <parent link="base_link"/>
    <child link="virtual_laser_link"/>
    <origin rpy="0.0 0.0 0" xyz="0.0 0.0 0.25"/>
  </joint>
  <link name="virtual_laser_link">
    </link>
  <joint name="base_link_to_front_laser_joint" type="fixed">
    <parent link="base_link"/>
    <child link="front_laser_link"/>
    <!--origin xyz="0.3564 0.2064 0.1914" rpy="0.0 0.0 ${0.25 * pi}" /-->
    <!-- MiR 250 Rviz-->
    <origin rpy="0.0 0.0 0.7853981633974483" xyz="0.3164 0.2064 0.1914"/>
    <!-- MiR 250 CAD-->
    <!--origin xyz="0.4288 0.2358 0.1914" rpy="0.0 0.0 ${0.25 * pi}" /-->
    <!-- from visually matching up the meshes of the MiR and the laser scanner -->
  </joint>
  <link name="front_laser_link">
    <visual>
      <origin rpy="3.141592653589793 0 0" xyz="0.0 0.0 0.0"/>
      <geometry>
        <mesh filename="package://mir_description/meshes/visual/sick_lms-100.stl"/>
      </geometry>
      <!-- <xacro:insert_block name="material_yellow" /> -->
      <material name="black">
        <color rgba="0.1 0.1 0.1 1"/>
      </material>
    </visual>
    <collision>
      <origin rpy="3.141592653589793 0 0" xyz="0.0 0.0 0.0"/>
      <geometry>
        <mesh filename="package://mir_description/meshes/visual/sick_lms-100.stl"/>
      </geometry>
    </collision>
    <inertial>
      <mass value="2.0"/>
      <origin xyz="0 0 0"/>
      <inertia ixx="0.009708329449999999" ixy="0.0" ixz="0.0" iyy="0.0097601627626" iyz="0.0" izz="0.0080601634426"/>
    </inertial>
  </link>
  <gazebo reference="front_laser_link">
    <!-- <material value="Gazebo/Yellow" /> -->
    <material value="Gazebo/FlatBlack"/>
    <sensor name="front_laser_link" type="ray">
      <visualize>false</visualize>
      <update_rate>12.5</update_rate>
      <ray>
        <scan>
          <horizontal>
            <samples>541</samples>
            <resolution>1</resolution>
            <!-- has to be 1; actual resolution will be computed from number of samples + min_angle/max_angle -->
            <min_angle>-2.09438</min_angle>
            <max_angle>2.09438</max_angle>
          </horizontal>
        </scan>
        <range>
          <min>0.05</min>
          <max>29.0</max>
          <resolution>0.01</resolution>
        </range>
        <noise>
          <type>gaussian</type>
          <!-- Noise parameters based on published spec for S300 achieving
                 "+-29mm" accuracy at range < 3m (~0.01 of the range) at
                 1 sigma. -->
          <mean>0.0</mean>
          <stddev>0.01</stddev>
        </noise>
      </ray>
      <plugin filename="libgazebo_ros_ray_sensor.so" name="gazebo_ros_front_laser_link_controller">
        <ros>
          <remapping>~/out:=f_scan</remapping>
        </ros>
        <output_type>sensor_msgs/LaserScan</output_type>
        <frame_name>front_laser_link</frame_name>
      </plugin>
    </sensor>
  </gazebo>
  <joint name="base_link_to_back_laser_joint" type="fixed">
    <parent link="base_link"/>
    <child link="back_laser_link"/>
    <!--origin xyz="-0.2764 -0.2064 0.1914" rpy="0.0 0.0 ${-0.75 * pi}" /-->
    <!-- MiR 250 Rviz-->
    <origin rpy="0.0 0.0 -2.356194490192345" xyz="-0.3164 -0.2064 0.1914"/>
    <!-- MiR 250 CAD-->
    <!--origin xyz="-0.3548 -0.2352 0.1914" rpy="0.0 0.0 ${-0.75 * pi}" /-->
    <!-- from visually matching up the meshes of the MiR and the laser scanner -->
  </joint>
  <link name="back_laser_link">
    <visual>
      <origin rpy="3.141592653589793 0 0" xyz="0.0 0.0 0.0"/>
      <geometry>
        <mesh filename="package://mir_description/meshes/visual/sick_lms-100.stl"/>
      </geometry>
      <!-- <xacro:insert_block name="material_yellow" /> -->
      <material name="black">
        <color rgba="0.1 0.1 0.1 1"/>
      </material>
    </visual>
    <collision>
      <origin rpy="3.141592653589793 0 0" xyz="0.0 0.0 0.0"/>
      <geometry>
        <mesh filename="package://mir_description/meshes/visual/sick_lms-100.stl"/>
      </geometry>
    </collision>
    <inertial>
      <mass value="2.0"/>
      <origin xyz="0 0 0"/>
      <inertia ixx="0.009708329449999999" ixy="0.0" ixz="0.0" iyy="0.0097601627626" iyz="0.0" izz="0.0080601634426"/>
    </inertial>
  </link>
  <gazebo reference="back_laser_link">
    <!-- <material value="Gazebo/Yellow" /> -->
    <material value="Gazebo/FlatBlack"/>
    <sensor name="back_laser_link" type="ray">
      <visualize>false</visualize>
      <update_rate>12.5</update_rate>
      <ray>
        <scan>
          <horizontal>
            <samples>541</samples>
            <resolution>1</resolution>
            <!-- has to be 1; actual resolution will be computed from number of samples + min_angle/max_angle -->
            <min_angle>-2.09438</min_angle>
            <max_angle>2.09438</max_angle>
          </horizontal>
        </scan>
        <range>
          <min>0.05</min>
          <max>29.0</max>
          <resolution>0.01</resolution>
        </range>
        <noise>
          <type>gaussian</type>
          <!-- Noise parameters based on published spec for S300 achieving
                 "+-29mm" accuracy at range < 3m (~0.01 of the range) at
                 1 sigma. -->
          <mean>0.0</mean>
          <stddev>0.01</stddev>
        </noise>
      </ray>
      <plugin filename="libgazebo_ros_ray_sensor.so" name="gazebo_ros_back_laser_link_controller">
        <ros>
          <remapping>~/out:=b_scan</remapping>
        </ros>
        <output_type>sensor_msgs/LaserScan</output_type>
        <frame_name>back_laser_link</frame_name>
      </plugin>
    </sensor>
  </gazebo>
  <!-- Ultrasound sensors -->
  <joint name="us_1_joint" type="fixed">
    <!-- right ultrasound -->
    <parent link="base_link"/>
    <child link="us_1_frame"/>
    <origin rpy="0 0 0" xyz="0.45 -0.12 0.16 "/>
    <!-- from visually matching to the mesh of the MiR -->
  </joint>
  <link name="us_1_frame"/>
  <joint name="us_2_joint" type="fixed">
    <!-- left ultrasound -->
    <parent link="base_link"/>
    <child link="us_2_frame"/>
    <origin rpy="0 0 0" xyz="0.45 0.12 0.16 "/>
    <!-- from visually matching to the mesh of the MiR -->
  </joint>
  <link name="us_2_frame"/>
  <joint name="left_wheel_joint" type="continuous">
    <origin rpy="0 0 0" xyz="0.0 0.2015 0.1"/>
    <parent link="base_link"/>
    <child link="left_wheel_link"/>
    <axis xyz="0 1 0"/>
    <limit effort="250" velocity="20.0"/>
    <!-- <dynamics damping="0.0" friction="0.0"/> -->
    <!-- <gazebo reference="${prefix}${locationprefix}_wheel_joint">
        <implicitSpringDamper>1</implicitSpringDamper>
      </gazebo> -->
  </joint>
  <link name="left_wheel_link">
    <inertial>
      <mass value="1.0"/>
      <origin rpy="1.5707963267948966 0 0" xyz="0 0 0"/>
      <inertia ixx="0.0026203322852000007" ixy="0.0" ixz="0.0" iyy="0.0026203322852000007" iyz="0.0" izz="0.005000000000000001"/>
    </inertial>
    <visual>
      <!--origin xyz="0 0 0" rpy="0 0 0" /-->
      <origin rpy="1.5707963267948966 0 0" xyz="0 0 0"/>
      <geometry>
        <!--mesh filename="package://mir_description/meshes/visual/wheel.stl" /-->
        <cylinder length="0.038" radius="0.1"/>
      </geometry>
      <material name="dark_grey">
        <color rgba="0.3 0.3 0.3 1"/>
      </material>
    </visual>
    <collision>
      <origin rpy="1.5707963267948966 0 0" xyz="0 0 0"/>
      <geometry>
        <cylinder length="0.038" radius="0.1"/>
      </geometry>
    </collision>
  </link>
  <gazebo reference="left_wheel_link">
    <material>Gazebo/DarkGrey</material>
  </gazebo>
  <!-- set the gazebo friction parameters for the wheels -->
  <gazebo reference="left_wheel_link">
    <!-- <mu1>1.6</mu1>
      <mu2>1.6</mu2>
      <min_depth>0.01</min_depth> -->
    <collision name="left_wheel_link_collision">
      <surface>
        <friction>
          <ode>
            <!-- <mu>300.0</mu>
                <mu2>300.0</mu2>
                <fdir1>0 0 1</fdir1> -->
            <mu>300.0</mu>
            <mu2>300.0</mu2>
            <fdir1>0 0 1</fdir1>
            <!-- <slip1>0</slip1>
                <slip2>0</slip2> -->
          </ode>
          <torsional>
            <coefficient>300</coefficient>
            <use_patch_radius>false</use_patch_radius>
            <surface_radius>0.1</surface_radius>
          </torsional>
        </friction>
        <contact>
          <ode>
            <!-- <soft_cfm>0.0</soft_cfm>
                <soft_erp>0.2</soft_erp> -->
            <!-- <kp>10000000.0</kp>
                <kd>1.0</kd>
                <max_vel>0.01</max_vel> -->
            <min_depth>0.001</min_depth>
            <!-- depth needed to have contact friction-->
          </ode>
        </contact>
      </surface>
    </collision>
  </gazebo>
  <joint name="right_wheel_joint" type="continuous">
    <origin rpy="0 0 0" xyz="0.0 -0.2015 0.1"/>
    <parent link="base_link"/>
    <child link="right_wheel_link"/>
    <axis xyz="0 1 0"/>
    <limit effort="250" velocity="20.0"/>
    <!-- <dynamics damping="0.0" friction="0.0"/> -->
    <!-- <gazebo reference="${prefix}${locationprefix}_wheel_joint">
        <implicitSpringDamper>1</implicitSpringDamper>
      </gazebo> -->
  </joint>
  <link name="right_wheel_link">
    <inertial>
      <mass value="1.0"/>
      <origin rpy="1.5707963267948966 0 0" xyz="0 0 0"/>
      <inertia ixx="0.0026203322852000007" ixy="0.0" ixz="0.0" iyy="0.0026203322852000007" iyz="0.0" izz="0.005000000000000001"/>
    </inertial>
    <visual>
      <!--origin xyz="0 0 0" rpy="0 0 0" /-->
      <origin rpy="1.5707963267948966 0 0" xyz="0 0 0"/>
      <geometry>
        <!--mesh filename="package://mir_description/meshes/visual/wheel.stl" /-->
        <cylinder length="0.038" radius="0.1"/>
      </geometry>
      <material name="dark_grey">
        <color rgba="0.3 0.3 0.3 1"/>
      </material>
    </visual>
    <collision>
      <origin rpy="1.5707963267948966 0 0" xyz="0 0 0"/>
      <geometry>
        <cylinder length="0.038" radius="0.1"/>
      </geometry>
    </collision>
  </link>
  <gazebo reference="right_wheel_link">
    <material>Gazebo/DarkGrey</material>
  </gazebo>
  <!-- set the gazebo friction parameters for the wheels -->
  <gazebo reference="right_wheel_link">
    <!-- <mu1>1.6</mu1>
      <mu2>1.6</mu2>
      <min_depth>0.01</min_depth> -->
    <collision name="right_wheel_link_collision">
      <surface>
        <friction>
          <ode>
            <!-- <mu>300.0</mu>
                <mu2>300.0</mu2>
                <fdir1>0 0 1</fdir1> -->
            <mu>300.0</mu>
            <mu2>300.0</mu2>
            <fdir1>0 0 1</fdir1>
            <!-- <slip1>0</slip1>
                <slip2>0</slip2> -->
          </ode>
          <torsional>
            <coefficient>300</coefficient>
            <use_patch_radius>false</use_patch_radius>
            <surface_radius>0.1</surface_radius>
          </torsional>
        </friction>
        <contact>
          <ode>
            <!-- <soft_cfm>0.0</soft_cfm>
                <soft_erp>0.2</soft_erp> -->
            <!-- <kp>10000000.0</kp>
                <kd>1.0</kd>
                <max_vel>0.01</max_vel> -->
            <min_depth>0.001</min_depth>
            <!-- depth needed to have contact friction-->
          </ode>
        </contact>
      </surface>
    </collision>
  </gazebo>
  <!-- caster hub -->
  <joint name="fl_caster_rotation_joint" type="continuous">
    <origin rpy="0 0 0" xyz="0.3037 0.188 0.1565"/>
    <parent link="base_link"/>
    <child link="fl_caster_rotation_link"/>
    <axis xyz="0 0 1"/>
    <dynamics damping="0.0" friction="0.0"/>
  </joint>
  <!-- <gazebo>
      <plugin name="${locationprefix}_caster_rotation_joint_states" filename="libgazebo_ros_joint_state_publisher.so">
        <ros>
          <namespace>${ns}</namespace>
        </ros>
        <update_rate>200.0</update_rate>
        <joint_name>${prefix}${locationprefix}_caster_rotation_joint</joint_name>
      </plugin>
    </gazebo> -->
  <link name="fl_caster_rotation_link">
    <inertial>
      <!-- <origin xyz="0 0 -0.042500000044" rpy="${0.5 * pi} ${24 * deg_to_rad} ${1.5 * pi}" /> -->
      <origin rpy="0.41887903200000004 0 1.5707963267948966 " xyz="0 0 -0.042500000044"/>
      <mass value="0.3097539019"/>
      <inertia ixx="0.0005844517978" ixy="0" ixz="0" iyy="0.00052872551237" iyz="0" izz="0.00017923555074"/>
    </inertial>
    <visual>
      <origin rpy="0 0 0" xyz="0 0 0"/>
      <geometry>
        <mesh filename="package://mir_description/meshes/visual/caster_wheel_base.stl"/>
      </geometry>
      <material name="silver">
        <color rgba="0.79 0.82 0.93 1"/>
      </material>
    </visual>
    <collision>
      <origin rpy="0 0 0" xyz="0 0 0"/>
      <geometry>
        <mesh filename="package://mir_description/meshes/collision/caster_wheel_base.stl"/>
      </geometry>
    </collision>
  </link>
  <gazebo reference="fl_caster_rotation_link">
    <material>Gazebo/Grey</material>
  </gazebo>
  <!-- caster wheel -->
  <joint name="fl_caster_wheel_joint" type="continuous">
    <origin rpy="0 0 0" xyz="-0.0382 0 -0.094"/>
    <parent link="fl_caster_rotation_link"/>
    <child link="fl_caster_wheel_link"/>
    <axis xyz="0 1 0"/>
  </joint>
  <!-- <gazebo>
      <plugin name="${locationprefix}_caster_wheel_joint_states" filename="libgazebo_ros_joint_state_publisher.so">
        <ros>
          <namespace>${ns}</namespace>
        </ros>
        <update_rate>200.0</update_rate>
        <joint_name>${prefix}${locationprefix}_caster_wheel_joint</joint_name>
      </plugin>
    </gazebo> -->
  <link name="fl_caster_wheel_link">
    <inertial>
      <mass value="1.0"/>
      <origin rpy="1.5707963267948966 0 0" xyz="0 0 0"/>
      <inertia ixx="0.001061895408575" ixy="0.0" ixz="0.0" iyy="0.001061895408575" iyz="0.0" izz="0.001953125"/>
    </inertial>
    <visual>
      <origin rpy="0 0 0" xyz="0 0 0"/>
      <geometry>
        <mesh filename="package://mir_description/meshes/visual/wheel.stl"/>
      </geometry>
      <material name="dark_grey">
        <color rgba="0.3 0.3 0.3 1"/>
      </material>
    </visual>
    <collision>
      <origin rpy="1.5707963267948966 0 0" xyz="0 0 0"/>
      <geometry>
        <!-- <cylinder radius="${mir_100_caster_wheel_radius}" length="${mir_100_caster_wheel_width}" /> -->
        <cylinder length="0.00001" radius="0.0625"/>
        <!-- <sphere radius="${mir_100_caster_wheel_radius}" /> -->
      </geometry>
    </collision>
  </link>
  <gazebo reference="fl_caster_wheel_link">
    <material>Gazebo/DarkGrey</material>
  </gazebo>
  <!-- set the gazebo friction parameters for the wheels -->
  <gazebo reference="fl_caster_wheel_link">
    <collision name="fl_caster_wheel_link_collision">
      <surface>
        <friction>
          <ode>
            <!-- <mu>1.0</mu>
                <mu2>1.0</mu2>
                <fdir1>0 0 1</fdir1>
                <slip1>0.0</slip1>
                <slip2>0.5</slip2> -->
            <mu>1.0</mu>
            <mu2>1.0</mu2>
            <fdir1>0 0 1</fdir1>
            <slip1>0.0</slip1>
            <slip2>0.5</slip2>
          </ode>
          <!-- <torsional>
                <coefficient>1.0</coefficient>
                <use_patch_radius>false</use_patch_radius>
                <surface_radius>${mir_100_caster_wheel_radius}</surface_radius>
              </torsional> -->
        </friction>
        <contact>
          <ode>
            <!-- <soft_cfm>0.0</soft_cfm>
                <soft_erp>0.2</soft_erp> -->
            <kp>100000000.0</kp>
            <!--<kd>1.0</kd> -->
            <!-- <max_vel>1.0</max_vel> -->
            <min_depth>0.0</min_depth>
          </ode>
        </contact>
      </surface>
    </collision>
  </gazebo>
  <!-- caster hub -->
  <joint name="fr_caster_rotation_joint" type="continuous">
    <origin rpy="0 0 0" xyz="0.3037 -0.188 0.1565"/>
    <parent link="base_link"/>
    <child link="fr_caster_rotation_link"/>
    <axis xyz="0 0 1"/>
    <dynamics damping="0.0" friction="0.0"/>
  </joint>
  <!-- <gazebo>
      <plugin name="${locationprefix}_caster_rotation_joint_states" filename="libgazebo_ros_joint_state_publisher.so">
        <ros>
          <namespace>${ns}</namespace>
        </ros>
        <update_rate>200.0</update_rate>
        <joint_name>${prefix}${locationprefix}_caster_rotation_joint</joint_name>
      </plugin>
    </gazebo> -->
  <link name="fr_caster_rotation_link">
    <inertial>
      <!-- <origin xyz="0 0 -0.042500000044" rpy="${0.5 * pi} ${24 * deg_to_rad} ${1.5 * pi}" /> -->
      <origin rpy="0.41887903200000004 0 1.5707963267948966 " xyz="0 0 -0.042500000044"/>
      <mass value="0.3097539019"/>
      <inertia ixx="0.0005844517978" ixy="0" ixz="0" iyy="0.00052872551237" iyz="0" izz="0.00017923555074"/>
    </inertial>
    <visual>
      <origin rpy="0 0 0" xyz="0 0 0"/>
      <geometry>
        <mesh filename="package://mir_description/meshes/visual/caster_wheel_base.stl"/>
      </geometry>
      <material name="silver">
        <color rgba="0.79 0.82 0.93 1"/>
      </material>
    </visual>
    <collision>
      <origin rpy="0 0 0" xyz="0 0 0"/>
      <geometry>
        <mesh filename="package://mir_description/meshes/collision/caster_wheel_base.stl"/>
      </geometry>
    </collision>
  </link>
  <gazebo reference="fr_caster_rotation_link">
    <material>Gazebo/Grey</material>
  </gazebo>
  <!-- caster wheel -->
  <joint name="fr_caster_wheel_joint" type="continuous">
    <origin rpy="0 0 0" xyz="-0.0382 0 -0.094"/>
    <parent link="fr_caster_rotation_link"/>
    <child link="fr_caster_wheel_link"/>
    <axis xyz="0 1 0"/>
  </joint>
  <!-- <gazebo>
      <plugin name="${locationprefix}_caster_wheel_joint_states" filename="libgazebo_ros_joint_state_publisher.so">
        <ros>
          <namespace>${ns}</namespace>
        </ros>
        <update_rate>200.0</update_rate>
        <joint_name>${prefix}${locationprefix}_caster_wheel_joint</joint_name>
      </plugin>
    </gazebo> -->
  <link name="fr_caster_wheel_link">
    <inertial>
      <mass value="1.0"/>
      <origin rpy="1.5707963267948966 0 0" xyz="0 0 0"/>
      <inertia ixx="0.001061895408575" ixy="0.0" ixz="0.0" iyy="0.001061895408575" iyz="0.0" izz="0.001953125"/>
    </inertial>
    <visual>
      <origin rpy="0 0 0" xyz="0 0 0"/>
      <geometry>
        <mesh filename="package://mir_description/meshes/visual/wheel.stl"/>
      </geometry>
      <material name="dark_grey">
        <color rgba="0.3 0.3 0.3 1"/>
      </material>
    </visual>
    <collision>
      <origin rpy="1.5707963267948966 0 0" xyz="0 0 0"/>
      <geometry>
        <!-- <cylinder radius="${mir_100_caster_wheel_radius}" length="${mir_100_caster_wheel_width}" /> -->
        <cylinder length="0.00001" radius="0.0625"/>
        <!-- <sphere radius="${mir_100_caster_wheel_radius}" /> -->
      </geometry>
    </collision>
  </link>
  <gazebo reference="fr_caster_wheel_link">
    <material>Gazebo/DarkGrey</material>
  </gazebo>
  <!-- set the gazebo friction parameters for the wheels -->
  <gazebo reference="fr_caster_wheel_link">
    <collision name="fr_caster_wheel_link_collision">
      <surface>
        <friction>
          <ode>
            <!-- <mu>1.0</mu>
                <mu2>1.0</mu2>
                <fdir1>0 0 1</fdir1>
                <slip1>0.0</slip1>
                <slip2>0.5</slip2> -->
            <mu>1.0</mu>
            <mu2>1.0</mu2>
            <fdir1>0 0 1</fdir1>
            <slip1>0.0</slip1>
            <slip2>0.5</slip2>
          </ode>
          <!-- <torsional>
                <coefficient>1.0</coefficient>
                <use_patch_radius>false</use_patch_radius>
                <surface_radius>${mir_100_caster_wheel_radius}</surface_radius>
              </torsional> -->
        </friction>
        <contact>
          <ode>
            <!-- <soft_cfm>0.0</soft_cfm>
                <soft_erp>0.2</soft_erp> -->
            <kp>100000000.0</kp>
            <!--<kd>1.0</kd> -->
            <!-- <max_vel>1.0</max_vel> -->
            <min_depth>0.0</min_depth>
          </ode>
        </contact>
      </surface>
    </collision>
  </gazebo>
  <!-- caster hub -->
  <joint name="bl_caster_rotation_joint" type="continuous">
    <origin rpy="0 0 0" xyz="-0.296 0.188 0.1565"/>
    <parent link="base_link"/>
    <child link="bl_caster_rotation_link"/>
    <axis xyz="0 0 1"/>
    <dynamics damping="0.0" friction="0.0"/>
  </joint>
  <!-- <gazebo>
      <plugin name="${locationprefix}_caster_rotation_joint_states" filename="libgazebo_ros_joint_state_publisher.so">
        <ros>
          <namespace>${ns}</namespace>
        </ros>
        <update_rate>200.0</update_rate>
        <joint_name>${prefix}${locationprefix}_caster_rotation_joint</joint_name>
      </plugin>
    </gazebo> -->
  <link name="bl_caster_rotation_link">
    <inertial>
      <!-- <origin xyz="0 0 -0.042500000044" rpy="${0.5 * pi} ${24 * deg_to_rad} ${1.5 * pi}" /> -->
      <origin rpy="0.41887903200000004 0 1.5707963267948966 " xyz="0 0 -0.042500000044"/>
      <mass value="0.3097539019"/>
      <inertia ixx="0.0005844517978" ixy="0" ixz="0" iyy="0.00052872551237" iyz="0" izz="0.00017923555074"/>
    </inertial>
    <visual>
      <origin rpy="0 0 0" xyz="0 0 0"/>
      <geometry>
        <mesh filename="package://mir_description/meshes/visual/caster_wheel_base.stl"/>
      </geometry>
      <material name="silver">
        <color rgba="0.79 0.82 0.93 1"/>
      </material>
    </visual>
    <collision>
      <origin rpy="0 0 0" xyz="0 0 0"/>
      <geometry>
        <mesh filename="package://mir_description/meshes/collision/caster_wheel_base.stl"/>
      </geometry>
    </collision>
  </link>
  <gazebo reference="bl_caster_rotation_link">
    <material>Gazebo/Grey</material>
  </gazebo>
  <!-- caster wheel -->
  <joint name="bl_caster_wheel_joint" type="continuous">
    <origin rpy="0 0 0" xyz="-0.0382 0 -0.094"/>
    <parent link="bl_caster_rotation_link"/>
    <child link="bl_caster_wheel_link"/>
    <axis xyz="0 1 0"/>
  </joint>
  <!-- <gazebo>
      <plugin name="${locationprefix}_caster_wheel_joint_states" filename="libgazebo_ros_joint_state_publisher.so">
        <ros>
          <namespace>${ns}</namespace>
        </ros>
        <update_rate>200.0</update_rate>
        <joint_name>${prefix}${locationprefix}_caster_wheel_joint</joint_name>
      </plugin>
    </gazebo> -->
  <link name="bl_caster_wheel_link">
    <inertial>
      <mass value="1.0"/>
      <origin rpy="1.5707963267948966 0 0" xyz="0 0 0"/>
      <inertia ixx="0.001061895408575" ixy="0.0" ixz="0.0" iyy="0.001061895408575" iyz="0.0" izz="0.001953125"/>
    </inertial>
    <visual>
      <origin rpy="0 0 0" xyz="0 0 0"/>
      <geometry>
        <mesh filename="package://mir_description/meshes/visual/wheel.stl"/>
      </geometry>
      <material name="dark_grey">
        <color rgba="0.3 0.3 0.3 1"/>
      </material>
    </visual>
    <collision>
      <origin rpy="1.5707963267948966 0 0" xyz="0 0 0"/>
      <geometry>
        <!-- <cylinder radius="${mir_100_caster_wheel_radius}" length="${mir_100_caster_wheel_width}" /> -->
        <cylinder length="0.00001" radius="0.0625"/>
        <!-- <sphere radius="${mir_100_caster_wheel_radius}" /> -->
      </geometry>
    </collision>
  </link>
  <gazebo reference="bl_caster_wheel_link">
    <material>Gazebo/DarkGrey</material>
  </gazebo>
  <!-- set the gazebo friction parameters for the wheels -->
  <gazebo reference="bl_caster_wheel_link">
    <collision name="bl_caster_wheel_link_collision">
      <surface>
        <friction>
          <ode>
            <!-- <mu>1.0</mu>
                <mu2>1.0</mu2>
                <fdir1>0 0 1</fdir1>
                <slip1>0.0</slip1>
                <slip2>0.5</slip2> -->
            <mu>1.0</mu>
            <mu2>1.0</mu2>
            <fdir1>0 0 1</fdir1>
            <slip1>0.0</slip1>
            <slip2>0.5</slip2>
          </ode>
          <!-- <torsional>
                <coefficient>1.0</coefficient>
                <use_patch_radius>false</use_patch_radius>
                <surface_radius>${mir_100_caster_wheel_radius}</surface_radius>
              </torsional> -->
        </friction>
        <contact>
          <ode>
            <!-- <soft_cfm>0.0</soft_cfm>
                <soft_erp>0.2</soft_erp> -->
            <kp>100000000.0</kp>
            <!--<kd>1.0</kd> -->
            <!-- <max_vel>1.0</max_vel> -->
            <min_depth>0.0</min_depth>
          </ode>
        </contact>
      </surface>
    </collision>
  </gazebo>
  <!-- caster hub -->
  <joint name="br_caster_rotation_joint" type="continuous">
    <origin rpy="0 0 0" xyz="-0.296 -0.188 0.1565"/>
    <parent link="base_link"/>
    <child link="br_caster_rotation_link"/>
    <axis xyz="0 0 1"/>
    <dynamics damping="0.0" friction="0.0"/>
  </joint>
  <!-- <gazebo>
      <plugin name="${locationprefix}_caster_rotation_joint_states" filename="libgazebo_ros_joint_state_publisher.so">
        <ros>
          <namespace>${ns}</namespace>
        </ros>
        <update_rate>200.0</update_rate>
        <joint_name>${prefix}${locationprefix}_caster_rotation_joint</joint_name>
      </plugin>
    </gazebo> -->
  <link name="br_caster_rotation_link">
    <inertial>
      <!-- <origin xyz="0 0 -0.042500000044" rpy="${0.5 * pi} ${24 * deg_to_rad} ${1.5 * pi}" /> -->
      <origin rpy="0.41887903200000004 0 1.5707963267948966 " xyz="0 0 -0.042500000044"/>
      <mass value="0.3097539019"/>
      <inertia ixx="0.0005844517978" ixy="0" ixz="0" iyy="0.00052872551237" iyz="0" izz="0.00017923555074"/>
    </inertial>
    <visual>
      <origin rpy="0 0 0" xyz="0 0 0"/>
      <geometry>
        <mesh filename="package://mir_description/meshes/visual/caster_wheel_base.stl"/>
      </geometry>
      <material name="silver">
        <color rgba="0.79 0.82 0.93 1"/>
      </material>
    </visual>
    <collision>
      <origin rpy="0 0 0" xyz="0 0 0"/>
      <geometry>
        <mesh filename="package://mir_description/meshes/collision/caster_wheel_base.stl"/>
      </geometry>
    </collision>
  </link>
  <gazebo reference="br_caster_rotation_link">
    <material>Gazebo/Grey</material>
  </gazebo>
  <!-- caster wheel -->
  <joint name="br_caster_wheel_joint" type="continuous">
    <origin rpy="0 0 0" xyz="-0.0382 0 -0.094"/>
    <parent link="br_caster_rotation_link"/>
    <child link="br_caster_wheel_link"/>
    <axis xyz="0 1 0"/>
  </joint>
  <!-- <gazebo>
      <plugin name="${locationprefix}_caster_wheel_joint_states" filename="libgazebo_ros_joint_state_publisher.so">
        <ros>
          <namespace>${ns}</namespace>
        </ros>
        <update_rate>200.0</update_rate>
        <joint_name>${prefix}${locationprefix}_caster_wheel_joint</joint_name>
      </plugin>
    </gazebo> -->
  <link name="br_caster_wheel_link">
    <inertial>
      <mass value="1.0"/>
      <origin rpy="1.5707963267948966 0 0" xyz="0 0 0"/>
      <inertia ixx="0.001061895408575" ixy="0.0" ixz="0.0" iyy="0.001061895408575" iyz="0.0" izz="0.001953125"/>
    </inertial>
    <visual>
      <origin rpy="0 0 0" xyz="0 0 0"/>
      <geometry>
        <mesh filename="package://mir_description/meshes/visual/wheel.stl"/>
      </geometry>
      <material name="dark_grey">
        <color rgba="0.3 0.3 0.3 1"/>
      </material>
    </visual>
    <collision>
      <origin rpy="1.5707963267948966 0 0" xyz="0 0 0"/>
      <geometry>
        <!-- <cylinder radius="${mir_100_caster_wheel_radius}" length="${mir_100_caster_wheel_width}" /> -->
        <cylinder length="0.00001" radius="0.0625"/>
        <!-- <sphere radius="${mir_100_caster_wheel_radius}" /> -->
      </geometry>
    </collision>
  </link>
  <gazebo reference="br_caster_wheel_link">
    <material>Gazebo/DarkGrey</material>
  </gazebo>
  <!-- set the gazebo friction parameters for the wheels -->
  <gazebo reference="br_caster_wheel_link">
    <collision name="br_caster_wheel_link_collision">
      <surface>
        <friction>
          <ode>
            <!-- <mu>1.0</mu>
                <mu2>1.0</mu2>
                <fdir1>0 0 1</fdir1>
                <slip1>0.0</slip1>
                <slip2>0.5</slip2> -->
            <mu>1.0</mu>
            <mu2>1.0</mu2>
            <fdir1>0 0 1</fdir1>
            <slip1>0.0</slip1>
            <slip2>0.5</slip2>
          </ode>
          <!-- <torsional>
                <coefficient>1.0</coefficient>
                <use_patch_radius>false</use_patch_radius>
                <surface_radius>${mir_100_caster_wheel_radius}</surface_radius>
              </torsional> -->
        </friction>
        <contact>
          <ode>
            <!-- <soft_cfm>0.0</soft_cfm>
                <soft_erp>0.2</soft_erp> -->
            <kp>100000000.0</kp>
            <!--<kd>1.0</kd> -->
            <!-- <max_vel>1.0</max_vel> -->
            <min_depth>0.0</min_depth>
          </ode>
        </contact>
      </surface>
    </collision>
  </gazebo>
  <joint name="base_link_surface_joint" type="fixed">
    <origin rpy="0 0 0" xyz="-0.004485 0 0.352"/>
    <parent link="base_link"/>
    <child link="surface"/>
    <axis xyz="0 0 1"/>
  </joint>
  <link name="surface"/>
  <joint name="power_unit_joint" type="fixed">
    <parent link="base_link"/>
    <child link="power_unit"/>
    <origin rpy="0 0 0" xyz="0 0 0.3"/>
  </joint>
  <link name="power_unit">
    <inertial>
      <mass value="63.7"/>
      <origin rpy="0 0 0" xyz="0.0 0.0 0.0"/>
      <inertia ixx="0.6900830573000001" ixy="0.0" ixz="0.0" iyy="1.5394160509000003" iyz="0.0" izz="1.8048326114"/>
    </inertial>
    <visual>
      <origin rpy="0 0 0" xyz="0 0 0.245"/>
      <geometry>
        <box size="0.73 0.56 0.49"/>
      </geometry>
      <!-- Add material and other visual properties if needed -->
      <material name="light_grey">
        <color rgba="0.6 0.6 0.6 1"/>
      </material>
    </visual>
    <collision>
      <origin rpy="0 0 0" xyz="0 0 0.245"/>
      <geometry>
        <box size="0.73 0.56 0.49"/>
      </geometry>
      <!-- Add other collision properties if needed -->
    </collision>
  </link>
  
e     
  <!-- create link fixed to the "world" -->
  <!-- <link name="world" />
    
    <joint name="world_joint" type="fixed">
      <parent link="${prefix}base_link" />
      <child link="world" />
      <origin xyz="0.135 0 0.79" rpy="0 0 ${0.5 * pi}" />
    </joint> -->
  <ros2_control name="ur" type="system">
    <hardware>
      <plugin>gazebo_ros2_control/GazeboSystem</plugin>
    </hardware>
    <joint name="ur_shoulder_pan_joint">
      <command_interface name="position"/>
      <command_interface name="velocity"/>
      <state_interface name="position">
        <!-- initial position for the FakeSystem and simulation -->
        <param name="initial_value">0</param>
      </state_interface>
      <state_interface name="velocity"/>
      <state_interface name="effort"/>
    </joint>
    <joint name="ur_shoulder_lift_joint">
      <command_interface name="position"/>
      <command_interface name="velocity"/>
      <state_interface name="position">
        <!-- initial position for the FakeSystem and simulation -->
        <param name="initial_value">-1.57</param>
      </state_interface>
      <state_interface name="velocity"/>
      <state_interface name="effort"/>
    </joint>
    <joint name="ur_elbow_joint">
      <command_interface name="position"/>
      <command_interface name="velocity"/>
      <state_interface name="position">
        <!-- initial position for the FakeSystem and simulation -->
        <param name="initial_value">0.0</param>
      </state_interface>
      <state_interface name="velocity"/>
      <state_interface name="effort"/>
    </joint>
    <joint name="ur_wrist_1_joint">
      <command_interface name="position"/>
      <command_interface name="velocity"/>
      <state_interface name="position">
        <!-- initial position for the FakeSystem and simulation -->
        <param name="initial_value">0</param>
      </state_interface>
      <state_interface name="velocity"/>
      <state_interface name="effort"/>
    </joint>
    <joint name="ur_wrist_2_joint">
      <command_interface name="position"/>
      <command_interface name="velocity"/>
      <state_interface name="position">
        <!-- initial position for the FakeSystem and simulation -->
        <param name="initial_value">1.57</param>
      </state_interface>
      <state_interface name="velocity"/>
      <state_interface name="effort"/>
    </joint>
    <joint name="ur_wrist_3_joint">
      <command_interface name="position"/>
      <command_interface name="velocity"/>
      <state_interface name="position">
        <!-- initial position for the FakeSystem and simulation -->
        <param name="initial_value">0.0</param>
      </state_interface>
      <state_interface name="velocity"/>
      <state_interface name="effort"/>
    </joint>
  </ros2_control>
  <!-- Add URDF transmission elements (for ros_control) -->
  <!--<xacro:ur_arm_transmission prefix="${prefix}" hw_interface="${transmission_hw_interface}" />-->
  <!-- Placeholder for ros2_control transmission which don't yet exist -->
  <!-- links -  main serial chain -->
  <link name="ur_base_link"/>
  <link name="ur_base_link_inertia">
    <visual>
      <origin rpy="0 0 3.141592653589793" xyz="0 0 0"/>
      <geometry>
        <mesh filename="file:///home/dikki/ros2_ws_simulation/install/ur_description/share/ur_description/meshes/ur5e/visual/base.dae"/>
      </geometry>
    </visual>
    <collision>
      <origin rpy="0 0 3.141592653589793" xyz="0 0 0"/>
      <geometry>
        <mesh filename="file:///home/dikki/ros2_ws_simulation/install/ur_description/share/ur_description/meshes/ur5e/collision/base.stl"/>
      </geometry>
    </collision>
    <inertial>
      <mass value="4.0"/>
      <origin rpy="0 0 0" xyz="0 0 0"/>
      <inertia ixx="0.00443333156" ixy="0.0" ixz="0.0" iyy="0.00443333156" iyz="0.0" izz="0.0072"/>
    </inertial>
  </link>
  <link name="ur_shoulder_link">
    <visual>
      <origin rpy="0 0 3.141592653589793" xyz="0 0 0"/>
      <geometry>
        <mesh filename="file:///home/dikki/ros2_ws_simulation/install/ur_description/share/ur_description/meshes/ur5e/visual/shoulder.dae"/>
      </geometry>
    </visual>
    <collision>
      <origin rpy="0 0 3.141592653589793" xyz="0 0 0"/>
      <geometry>
        <mesh filename="file:///home/dikki/ros2_ws_simulation/install/ur_description/share/ur_description/meshes/ur5e/collision/shoulder.stl"/>
      </geometry>
    </collision>
    <inertial>
      <mass value="3.761"/>
      <origin rpy="1.570796326794897 0 0" xyz="0.0 -0.00193 -0.02561"/>
      <inertia ixx="0.0070021" ixy="7.3e-07" ixz="-1.053e-05" iyy="0.00648091" iyz="0.00049994" izz="0.00657286"/>
    </inertial>
  </link>
  <link name="ur_upper_arm_link">
    <visual>
      <origin rpy="1.5707963267948966 0 -1.5707963267948966" xyz="0 0 0.138"/>
      <geometry>
        <mesh filename="file:///home/dikki/ros2_ws_simulation/install/ur_description/share/ur_description/meshes/ur5e/visual/upperarm.dae"/>
      </geometry>
    </visual>
    <collision>
      <origin rpy="1.5707963267948966 0 -1.5707963267948966" xyz="0 0 0.138"/>
      <geometry>
        <mesh filename="file:///home/dikki/ros2_ws_simulation/install/ur_description/share/ur_description/meshes/ur5e/collision/upperarm.stl"/>
      </geometry>
    </collision>
    <inertial>
      <mass value="8.058"/>
      <origin rpy="0 0 0" xyz="-0.2125 0.0 0.11336"/>
      <inertia ixx="0.01505885" ixy="-5.4e-05" ixz="5.63e-06" iyy="0.33388086" iyz="-1.81e-06" izz="0.33247207"/>
    </inertial>
  </link>
  <link name="ur_forearm_link">
    <visual>
      <origin rpy="1.5707963267948966 0 -1.5707963267948966" xyz="0 0 0.007"/>
      <geometry>
        <mesh filename="file:///home/dikki/ros2_ws_simulation/install/ur_description/share/ur_description/meshes/ur5e/visual/forearm.dae"/>
      </geometry>
    </visual>
    <collision>
      <origin rpy="1.5707963267948966 0 -1.5707963267948966" xyz="0 0 0.007"/>
      <geometry>
        <mesh filename="file:///home/dikki/ros2_ws_simulation/install/ur_description/share/ur_description/meshes/ur5e/collision/forearm.stl"/>
      </geometry>
    </collision>
    <inertial>
      <mass value="2.846"/>
      <origin rpy="0 0 0" xyz="-0.2422 0.0 0.0265"/>
      <inertia ixx="0.00399632" ixy="-1.365e-05" ixz="0.00137272" iyy="0.07879254" iyz="-6.6e-06" izz="0.0784851"/>
    </inertial>
  </link>
  <link name="ur_wrist_1_link">
    <visual>
      <origin rpy="1.5707963267948966 0 0" xyz="0 0 -0.127"/>
      <geometry>
        <mesh filename="file:///home/dikki/ros2_ws_simulation/install/ur_description/share/ur_description/meshes/ur5e/visual/wrist1.dae"/>
      </geometry>
    </visual>
    <collision>
      <origin rpy="1.5707963267948966 0 0" xyz="0 0 -0.127"/>
      <geometry>
        <mesh filename="file:///home/dikki/ros2_ws_simulation/install/ur_description/share/ur_description/meshes/ur5e/collision/wrist1.stl"/>
      </geometry>
    </collision>
    <inertial>
      <mass value="1.37"/>
      <origin rpy="1.570796326794897 0 0" xyz="0.0 -0.01634 -0.0018"/>
      <inertia ixx="0.00165491" ixy="-2.82e-06" ixz="-4.38e-06" iyy="0.00135962" iyz="0.00010157" izz="0.00126279"/>
    </inertial>
  </link>
  <link name="ur_wrist_2_link">
    <visual>
      <origin rpy="0 0 0" xyz="0 0 -0.0997"/>
      <geometry>
        <mesh filename="file:///home/dikki/ros2_ws_simulation/install/ur_description/share/ur_description/meshes/ur5e/visual/wrist2.dae"/>
      </geometry>
    </visual>
    <collision>
      <origin rpy="0 0 0" xyz="0 0 -0.0997"/>
      <geometry>
        <mesh filename="file:///home/dikki/ros2_ws_simulation/install/ur_description/share/ur_description/meshes/ur5e/collision/wrist2.stl"/>
      </geometry>
    </collision>
    <inertial>
      <mass value="1.3"/>
      <origin rpy="-1.570796326794897 0 0" xyz="0.0 0.01634 -0.0018"/>
      <inertia ixx="0.00135617" ixy="-2.74e-06" ixz="4.44e-06" iyy="0.00127827" iyz="-5.048e-05" izz="0.00096614"/>
    </inertial>
  </link>
  <link name="ur_wrist_3_link">
    <visual>
      <origin rpy="1.5707963267948966 0 0" xyz="0 0 -0.0989"/>
      <geometry>
        <mesh filename="file:///home/dikki/ros2_ws_simulation/install/ur_description/share/ur_description/meshes/ur5e/visual/wrist3.dae"/>
      </geometry>
    </visual>
    <collision>
      <origin rpy="1.5707963267948966 0 0" xyz="0 0 -0.0989"/>
      <geometry>
        <mesh filename="file:///home/dikki/ros2_ws_simulation/install/ur_description/share/ur_description/meshes/ur5e/collision/wrist3.stl"/>
      </geometry>
    </collision>
    <inertial>
      <mass value="0.365"/>
      <origin rpy="0 0 0" xyz="0.0 0.0 -0.001159"/>
      <inertia ixx="0.00018694" ixy="6e-08" ixz="-1.7e-07" iyy="0.00018908" iyz="-9.2e-07" izz="0.00025756"/>
    </inertial>
  </link>
  <!-- base_joint fixes base_link to the environment -->
  <joint name="ur_base_joint" type="fixed">
    <origin rpy="0 0 -1.5707963267948966" xyz="0.135 0 0.79"/>
    <parent link="base_link"/>
    <child link="ur_base_link"/>
  </joint>
  <!-- joints - main serial chain -->
  <joint name="ur_base_link-base_link_inertia" type="fixed">
    <parent link="ur_base_link"/>
    <child link="ur_base_link_inertia"/>
    <!-- 'base_link' is REP-103 aligned (so X+ forward), while the internal
           frames of the robot/controller have X+ pointing backwards.
           Use the joint between 'base_link' and 'base_link_inertia' (a dummy
           link/frame) to introduce the necessary rotation over Z (of pi rad).
      -->
    <origin rpy="0 0 3.141592653589793" xyz="0 0 0"/>
  </joint>
  <joint name="ur_shoulder_pan_joint" type="revolute">
    <parent link="ur_base_link_inertia"/>
    <child link="ur_shoulder_link"/>
    <origin rpy="0 0 0" xyz="0 0 0.1625"/>
    <axis xyz="0 0 1"/>
    <limit effort="150.0" lower="-6.283185307179586" upper="6.283185307179586" velocity="3.141592653589793"/>
    <dynamics damping="0" friction="0"/>
  </joint>
  <joint name="ur_shoulder_lift_joint" type="revolute">
    <parent link="ur_shoulder_link"/>
    <child link="ur_upper_arm_link"/>
    <origin rpy="1.570796327 0 0" xyz="0 0 0"/>
    <axis xyz="0 0 1"/>
    <limit effort="150.0" lower="-6.283185307179586" upper="6.283185307179586" velocity="3.141592653589793"/>
    <dynamics damping="0" friction="0"/>
  </joint>
  <joint name="ur_elbow_joint" type="revolute">
    <parent link="ur_upper_arm_link"/>
    <child link="ur_forearm_link"/>
    <origin rpy="0 0 0" xyz="-0.425 0 0"/>
    <axis xyz="0 0 1"/>
    <limit effort="150.0" lower="-3.141592653589793" upper="3.141592653589793" velocity="3.141592653589793"/>
    <dynamics damping="0" friction="0"/>
  </joint>
  <joint name="ur_wrist_1_joint" type="revolute">
    <parent link="ur_forearm_link"/>
    <child link="ur_wrist_1_link"/>
    <origin rpy="0 0 0" xyz="-0.3922 0 0.1333"/>
    <axis xyz="0 0 1"/>
    <limit effort="28.0" lower="-6.283185307179586" upper="6.283185307179586" velocity="3.141592653589793"/>
    <dynamics damping="0" friction="0"/>
  </joint>
  <joint name="ur_wrist_2_joint" type="revolute">
    <parent link="ur_wrist_1_link"/>
    <child link="ur_wrist_2_link"/>
    <origin rpy="1.570796327 0 0" xyz="0 -0.0997 -2.044881182297852e-11"/>
    <axis xyz="0 0 1"/>
    <limit effort="28.0" lower="-6.283185307179586" upper="6.283185307179586" velocity="3.141592653589793"/>
    <dynamics damping="0" friction="0"/>
  </joint>
  <joint name="ur_wrist_3_joint" type="revolute">
    <parent link="ur_wrist_2_link"/>
    <child link="ur_wrist_3_link"/>
    <origin rpy="1.570796326589793 3.141592653589793 3.141592653589793" xyz="0 0.0996 -2.042830148012698e-11"/>
    <axis xyz="0 0 1"/>
    <limit effort="28.0" lower="-6.283185307179586" upper="6.283185307179586" velocity="3.141592653589793"/>
    <dynamics damping="0" friction="0"/>
  </joint>
  <link name="ur_ft_frame"/>
  <joint name="ur_wrist_3_link-ft_frame" type="fixed">
    <parent link="ur_wrist_3_link"/>
    <child link="ur_ft_frame"/>
    <origin rpy="3.141592653589793 0 0" xyz="0 0 0"/>
  </joint>
  <!-- ROS-Industrial 'base' frame - base_link to UR 'Base' Coordinates transform -->
  <link name="ur_base"/>
  <joint name="ur_base_link-base_fixed_joint" type="fixed">
    <!-- Note the rotation over Z of pi radians - as base_link is REP-103
           aligned (i.e., has X+ forward, Y+ left and Z+ up), this is needed
           to correctly align 'base' with the 'Base' coordinate system of
           the UR controller.
      -->
    <origin rpy="0 0 3.141592653589793" xyz="0 0 0"/>
    <parent link="ur_base_link"/>
    <child link="ur_base"/>
  </joint>
  <!-- ROS-Industrial 'flange' frame - attachment point for EEF models -->
  <link name="ur_flange"/>
  <joint name="ur_wrist_3-flange" type="fixed">
    <parent link="ur_wrist_3_link"/>
    <child link="ur_flange"/>
    <origin rpy="0 -1.5707963267948966 -1.5707963267948966" xyz="0 0 0"/>
  </joint>
  <!-- ROS-Industrial 'tool0' frame - all-zeros tool frame -->
  <link name="ur_tool0"/>
  <joint name="ur_flange-tool0" type="fixed">
    <!-- default toolframe - X+ left, Y+ up, Z+ front -->
    <origin rpy="1.5707963267948966 0 1.5707963267948966" xyz="0 0 0"/>
    <parent link="ur_flange"/>
    <child link="ur_tool0"/>
  </joint>
  <!-- sirf Gazebo simulation mein ye plugin load hoga, real hardware mein nahi. -->
  <link name="camera_mount">
    <visual>
      <origin rpy="0 0 0" xyz="0 0 0"/>
      <geometry>
        <mesh filename="package://mir_description/meshes/visual/D435i_mounted.STL" scale="0.001 0.001 0.001"/>
      </geometry>
      <material name="light_grey">
        <color rgba="0.6 0.6 0.6 1"/>
      </material>
    </visual>
    <collision>
      <origin rpy="0 0 0" xyz="0 0 0"/>
      <geometry>
        <mesh filename="package://mir_description/meshes/collision/D435i_mounted.STL" scale="0.001 0.001 0.001"/>
      </geometry>
    </collision>
  </link>
  <joint name="camera_mount_joint" type="fixed">
    <parent link="ur_flange"/>
    <child link="camera_mount"/>
    <origin rpy="0 3.141592653589793 1.5707963267948966" xyz="0.035 0.05 0.03"/>
  </joint>
  <!-- camera body, with origin at bottom screw mount -->
  <joint name="realsense_joint" type="fixed">
    <origin rpy="3.141592653589793 0 0" xyz="0.02 0 -0.061"/>
    <parent link="ur_flange"/>
    <child link="realsense_bottom_screw_frame"/>
  </joint>
  <link name="realsense_bottom_screw_frame"/>
  <joint name="realsense_link_joint" type="fixed">
    <origin rpy="0 0 0" xyz="0.010600000000000002 0.0175 0.0125"/>
    <parent link="realsense_bottom_screw_frame"/>
    <child link="realsense_link"/>
  </joint>
  <link name="realsense_link">
    <visual>
      <!-- the mesh origin is at front plate in between the two infrared camera axes -->
      <origin rpy="1.5707963267948966 0 1.5707963267948966" xyz="0.0043 -0.0175 0"/>
      <geometry>
        <mesh filename="file:///home/dikki/ros2_ws_simulation/install/realsense2_description/share/realsense2_description/meshes/d435.dae"/>
      </geometry>
    </visual>
    <collision>
      <origin rpy="0 0 0" xyz="0 -0.0175 0"/>
      <geometry>
        <box size="0.02505 0.09 0.025"/>
      </geometry>
    </collision>
    <inertial>
      <!-- The following are not reliable values, and should not be used for modeling -->
      <mass value="0.072"/>
      <!-- 0.072-->
      <origin xyz="0 0 0"/>
      <inertia ixx="0.000003881243" ixy="0.0" ixz="0.0" iyy="0.000498940" iyz="0.0" izz="0.000003879257"/>
    </inertial>
  </link>
  <!-- camera depth joints and links -->
  <joint name="realsense_depth_joint" type="fixed">
    <origin rpy="0 0 0" xyz="0 0 0"/>
    <parent link="realsense_link"/>
    <child link="realsense_depth_frame"/>
  </joint>
  <link name="realsense_depth_frame"/>
  <joint name="realsense_depth_optical_joint" type="fixed">
    <origin rpy="-1.5707963267948966 0 -1.5707963267948966" xyz="0 0 0"/>
    <parent link="realsense_depth_frame"/>
    <child link="realsense_depth_optical_frame"/>
  </joint>
  <link name="realsense_depth_optical_frame"/>
  <!-- camera left IR joints and links -->
  <joint name="realsense_infra1_joint" type="fixed">
    <origin rpy="0 0 0" xyz="0 0.0 0"/>
    <parent link="realsense_link"/>
    <child link="realsense_infra1_frame"/>
  </joint>
  <link name="realsense_infra1_frame"/>
  <joint name="realsense_infra1_optical_joint" type="fixed">
    <origin rpy="-1.5707963267948966 0 -1.5707963267948966" xyz="0 0 0"/>
    <parent link="realsense_infra1_frame"/>
    <child link="realsense_infra1_optical_frame"/>
  </joint>
  <link name="realsense_infra1_optical_frame"/>
  <!-- camera right IR joints and links -->
  <joint name="realsense_infra2_joint" type="fixed">
    <origin rpy="0 0 0" xyz="0 -0.05 0"/>
    <parent link="realsense_link"/>
    <child link="realsense_infra2_frame"/>
  </joint>
  <link name="realsense_infra2_frame"/>
  <joint name="realsense_infra2_optical_joint" type="fixed">
    <origin rpy="-1.5707963267948966 0 -1.5707963267948966" xyz="0 0 0"/>
    <parent link="realsense_infra2_frame"/>
    <child link="realsense_infra2_optical_frame"/>
  </joint>
  <link name="realsense_infra2_optical_frame"/>
  <!-- camera color joints and links -->
  <joint name="realsense_color_joint" type="fixed">
    <origin rpy="0 0 0" xyz="0 0.015 0"/>
    <parent link="realsense_link"/>
    <child link="realsense_color_frame"/>
  </joint>
  <link name="realsense_color_frame"/>
  <joint name="realsense_color_optical_joint" type="fixed">
    <origin rpy="-1.5707963267948966 0 -1.5707963267948966" xyz="0 0 0"/>
    <parent link="realsense_color_frame"/>
    <child link="realsense_color_optical_frame"/>
  </joint>
  <link name="realsense_color_optical_frame"/>
  <link name="realsense_accel_frame"/>
  <link name="realsense_accel_optical_frame"/>
  <link name="realsense_gyro_frame"/>
  <link name="realsense_gyro_optical_frame"/>
  <joint name="realsense_accel_joint" type="fixed">
    <origin rpy="0 0 0" xyz="-0.01174 -0.00552 0.0051"/>
    <parent link="realsense_link"/>
    <child link="realsense_accel_frame"/>
  </joint>
  <joint name="realsense_accel_optical_joint" type="fixed">
    <origin rpy="-1.5707963267948966 0 -1.5707963267948966" xyz="0 0 0"/>
    <parent link="realsense_accel_frame"/>
    <child link="realsense_accel_optical_frame"/>
  </joint>
  <joint name="realsense_gyro_joint" type="fixed">
    <origin rpy="0 0 0" xyz="-0.01174 -0.00552 0.0051"/>
    <parent link="realsense_link"/>
    <child link="realsense_gyro_frame"/>
  </joint>
  <joint name="realsense_gyro_optical_joint" type="fixed">
    <origin rpy="-1.5707963267948966 0 -1.5707963267948966" xyz="0 0 0"/>
    <parent link="realsense_gyro_frame"/>
    <child link="realsense_gyro_optical_frame"/>
  </joint>
  <gazebo reference="realsense_link">
    <self_collide>0</self_collide>
    <enable_wind>0</enable_wind>
    <kinematic>0</kinematic>
    <!-- <gravity>1</gravity> -->
    <!--<mu>1</mu>-->
    <mu2>1</mu2>
    <fdir1>0 0 0</fdir1>
    <!--<slip1>0</slip1>
      <slip2>0</slip2>-->
    <kp>1e+13</kp>
    <kd>1</kd>
    <!--<max_vel>0.01</max_vel>
      <min_depth>0</min_depth>-->
    <sensor name="realsensecolor" type="camera">
      <camera name="realsense">
        <horizontal_fov>1.2112585008840648</horizontal_fov>
        <image>
          <width>1920</width>
          <height>1080</height>
          <format>RGB_INT8</format>
        </image>
        <clip>
          <near>0.1</near>
          <far>100</far>
        </clip>
        <noise>
          <type>gaussian</type>
          <mean>0.0</mean>
          <stddev>0.007</stddev>
        </noise>
      </camera>
      <always_on>1</always_on>
      <update_rate>30</update_rate>
      <visualize>True</visualize>
    </sensor>
    <sensor name="realsenseired1" type="camera">
      <camera name="realsense">
        <horizontal_fov>1.4870205226991688</horizontal_fov>
        <image>
          <width>848</width>
          <height>480</height>
          <format>L_INT8</format>
        </image>
        <clip>
          <near>0.1</near>
          <far>100</far>
        </clip>
        <noise>
          <type>gaussian</type>
          <mean>0.0</mean>
          <stddev>0.05</stddev>
        </noise>
      </camera>
      <always_on>1</always_on>
      <update_rate>60</update_rate>
      <visualize>false</visualize>
    </sensor>
    <sensor name="realsenseired2" type="camera">
      <camera name="realsense">
        <horizontal_fov>1.4870205226991688</horizontal_fov>
        <image>
          <width>848</width>
          <height>480</height>
          <format>L_INT8</format>
        </image>
        <clip>
          <near>0.1</near>
          <far>100</far>
        </clip>
        <noise>
          <type>gaussian</type>
          <mean>0.0</mean>
          <stddev>0.05</stddev>
        </noise>
      </camera>
      <always_on>1</always_on>
      <update_rate>60</update_rate>
      <visualize>false</visualize>
    </sensor>
    <sensor name="realsensedepth" type="depth">
      <camera name="realsense">
        <horizontal_fov>1.4870205226991688</horizontal_fov>
        <image>
          <width>848</width>
          <height>480</height>
        </image>
        <clip>
          <near>0.1</near>
          <far>100</far>
        </clip>
        <noise>
          <type>gaussian</type>
          <mean>0.0</mean>
          <stddev>0.100</stddev>
        </noise>
      </camera>
      <always_on>1</always_on>
      <update_rate>60</update_rate>
      <visualize>false</visualize>
    </sensor>
    <!-- IMU -->
    <sensor name="realsenseimu" type="imu">
      <always_on>true</always_on>
      <update_rate>200</update_rate>
      <!-- <topic>${camera_name}/imu/sample</topic> -->
      <topic>__default_topic__</topic>
      <plugin filename="libgazebo_ros_imu_sensor.so" name="realsenseimu">
        <ros>
          <!-- Will publish to /camera/imu -->
          <!-- <namespace>${camera_name}/imu</namespace> -->
          <namespace>/camera</namespace>
          <remapping>~/out:=imu</remapping>
        </ros>
        <bodyName>realsense_link</bodyName>
        <frameName>realsense_gyro_optical_frame</frameName>
        <updateRateHZ>200</updateRateHZ>
        <gaussianNoise>0.1</gaussianNoise>
        <xyzOffset>0 0 0</xyzOffset>
        <rpyOffset>0 0 0</rpyOffset>
      </plugin>
    </sensor>
  </gazebo>
  <gazebo>
    <plugin filename="librealsense_gazebo_plugin.so" name="camera">
      <prefix>realsense</prefix>
      <!-- Color camera settings -->
      <colorUpdateRate>30</colorUpdateRate>
      <colorTopicName>camera/color/image_raw</colorTopicName>
      <colorOpticalframeName>realsense_color_optical_frame</colorOpticalframeName>
      <colorCameraInfoTopicName>color/camera_info</colorCameraInfoTopicName>
      <!-- Infrared camera settings -->
      <infraredUpdateRate>60</infraredUpdateRate>
      <infrared1TopicName>camera/infra1/image_rect_raw</infrared1TopicName>
      <infrared2TopicName>camera/infra2/image_rect_raw</infrared2TopicName>
      <infrared1CameraInfoTopicName>camera/infra1/camera_info</infrared1CameraInfoTopicName>
      <infrared2CameraInfoTopicName>camera/infra2/camera_info</infrared2CameraInfoTopicName>
      <infrared1OpticalframeName>realsense_left_ir_optical_frame</infrared1OpticalframeName>
      <infrared2OpticalframeName>realsense_right_ir_optical_frame</infrared2OpticalframeName>
      <!-- Depth camera settings -->
      <rangeMinDepth>0.2</rangeMinDepth>
      <rangeMaxDepth>10.0</rangeMaxDepth>
      <depthUpdateRate>60</depthUpdateRate>
      <depthTopicName>camera/depth/image_rect_raw</depthTopicName>
      <depthCameraInfoTopicName>camera/depth/camera_info</depthCameraInfoTopicName>
      <depthOpticalframeName>realsense_depth_optical_frame</depthOpticalframeName>
      <!-- Pointlcloud settings -->
      <pointCloud>True</pointCloud>
      <pointCloudTopicName>depth/color/points</pointCloudTopicName>
      <pointCloudCutoff>0.5</pointCloudCutoff>
      <!-- <ros>
                    <namespace>/camera</namespace>
                </ros> -->
    </plugin>
  </gazebo>
  <material name="Grey">
    <color rgba="0.2 0.2 0.2 1"/>
  </material>
  <material name="Blue">
    <color rgba="0 0 1 1"/>
  </material>
  <joint name="gripper_soft_robotics_gripper_base_joint" type="fixed">
    <!-- <origin xyz="0 0 0" rpy="0 0 0" /> -->
    <origin rpy="0 0 1.5707963267948966 " xyz="0 0 0"/>
    <parent link="ur_tool0"/>
    <child link="gripper_soft_robotics_gripper_base_link"/>
  </joint>
  <link name="gripper_soft_robotics_gripper_base_link">
    <visual>
      <origin rpy="0 0 0" xyz="0 0 -0.0095"/>
      <geometry>
        <mesh filename="file:///home/dikki/ros2_ws_simulation/install/gripper_description/share/gripper_description/models/meshes/base.stl"/>
      </geometry>
      <material name="Grey"/>
    </visual>
    <collision>
      <origin rpy="0 0 0" xyz="0 0 -0.0095"/>
      <geometry>
        <mesh filename="file:///home/dikki/ros2_ws_simulation/install/gripper_description/share/gripper_description/models/meshes/base.stl"/>
      </geometry>
    </collision>
    <inertial>
      <origin rpy="0 0 0" xyz="2.073e-05   1.45286e-03  -1.1049e-03"/>
      <mass value="0.168"/>
      <inertia ixx="6.69695624e-05" ixy="5.21511788e-09" ixz="-2.74383009e-08" iyy="7.85088161e-05" iyz="5.41105193e-07" izz="1.41819717e-04"/>
    </inertial>
  </link>
  <joint name="gripper_soft_robotics_gripper_left_finger_joint1" type="revolute">
    <origin rpy=" 0 0 0" xyz="0 -0.028 0.09"/>
    <parent link="gripper_soft_robotics_gripper_base_link"/>
    <child link="gripper_soft_robotics_left_finger_link1"/>
    <limit effort="1" lower="-0.35" upper="0.35" velocity="1"/>
    <axis xyz="1 0 0"/>
  </joint>
  <link name="gripper_soft_robotics_left_finger_link1">
    <visual>
      <origin rpy="0 0 0" xyz="0 0 0"/>
      <geometry>
        <mesh filename="file:///home/dikki/ros2_ws_simulation/install/gripper_description/share/gripper_description/models/meshes/link1.stl"/>
      </geometry>
      <material name="Blue"/>
    </visual>
    <collision>
      <origin rpy="0 0 0" xyz="0 0 0"/>
      <geometry>
        <mesh filename="file:///home/dikki/ros2_ws_simulation/install/gripper_description/share/gripper_description/models/meshes/link1.stl"/>
      </geometry>
    </collision>
    <inertial>
      <origin rpy="0 0 0" xyz="2.073e-05   1.45286e-03  -1.1049e-03"/>
      <mass value="0.168"/>
      <inertia ixx="6.69695624e-05" ixy="5.21511788e-09" ixz="-2.74383009e-08" iyy="7.85088161e-05" iyz="5.41105193e-07" izz="1.41819717e-04"/>
    </inertial>
  </link>
  <joint name="gripper_soft_robotics_gripper_right_finger_joint1" type="revolute">
    <origin rpy=" 0 0 -3.141592653589793" xyz="0 0.028 0.09"/>
    <parent link="gripper_soft_robotics_gripper_base_link"/>
    <child link="gripper_soft_robotics_right_finger_link1"/>
    <limit effort="1" lower="-0.35" upper="0.35" velocity="1"/>
    <axis xyz="1 0 0"/>
  </joint>
  <link name="gripper_soft_robotics_right_finger_link1">
    <visual>
      <origin rpy="0 0 0" xyz="0 0 0"/>
      <geometry>
        <mesh filename="file:///home/dikki/ros2_ws_simulation/install/gripper_description/share/gripper_description/models/meshes/link1.stl"/>
      </geometry>
      <material name="Blue"/>
    </visual>
    <collision>
      <origin rpy="0 0 0" xyz="0 0 0"/>
      <geometry>
        <mesh filename="file:///home/dikki/ros2_ws_simulation/install/gripper_description/share/gripper_description/models/meshes/link1.stl"/>
      </geometry>
    </collision>
    <inertial>
      <origin rpy="0 0 0" xyz="2.073e-05   1.45286e-03  -1.1049e-03"/>
      <mass value="0.168"/>
      <inertia ixx="6.69695624e-05" ixy="5.21511788e-09" ixz="-2.74383009e-08" iyy="7.85088161e-05" iyz="5.41105193e-07" izz="1.41819717e-04"/>
    </inertial>
  </link>
  <joint name="gripper_soft_robotics_gripper_left_finger_joint2" type="fixed">
    <origin rpy=" 0 0 0" xyz="0 0.009 0.042"/>
    <parent link="gripper_soft_robotics_left_finger_link1"/>
    <child link="gripper_soft_robotics_left_finger_link2"/>
  </joint>
  <link name="gripper_soft_robotics_left_finger_link2">
    <visual>
      <geometry>
        <mesh filename="file:///home/dikki/ros2_ws_simulation/install/gripper_description/share/gripper_description/models/meshes/link2.stl"/>
      </geometry>
      <material name="Blue"/>
    </visual>
    <collision>
      <geometry>
        <mesh filename="file:///home/dikki/ros2_ws_simulation/install/gripper_description/share/gripper_description/models/meshes/link2.stl"/>
      </geometry>
    </collision>
    <inertial>
      <origin rpy="0 0 0" xyz="2.073e-05   1.45286e-03  -1.1049e-03"/>
      <mass value="0.168"/>
      <inertia ixx="6.69695624e-05" ixy="5.21511788e-09" ixz="-2.74383009e-08" iyy="7.85088161e-05" iyz="5.41105193e-07" izz="1.41819717e-04"/>
    </inertial>
  </link>
  <joint name="gripper_soft_robotics_gripper_right_finger_joint2" type="fixed">
    <origin rpy=" 0 0 0" xyz="0 0.009 0.042"/>
    <parent link="gripper_soft_robotics_right_finger_link1"/>
    <child link="gripper_soft_robotics_right_finger_link2"/>
  </joint>
  <link name="gripper_soft_robotics_right_finger_link2">
    <visual>
      <geometry>
        <mesh filename="file:///home/dikki/ros2_ws_simulation/install/gripper_description/share/gripper_description/models/meshes/link2.stl"/>
      </geometry>
      <material name="Blue"/>
    </visual>
    <collision>
      <geometry>
        <mesh filename="file:///home/dikki/ros2_ws_simulation/install/gripper_description/share/gripper_description/models/meshes/link2.stl"/>
      </geometry>
    </collision>
    <inertial>
      <origin rpy="0 0 0" xyz="2.073e-05   1.45286e-03  -1.1049e-03"/>
      <mass value="0.168"/>
      <inertia ixx="6.69695624e-05" ixy="5.21511788e-09" ixz="-2.74383009e-08" iyy="7.85088161e-05" iyz="5.41105193e-07" izz="1.41819717e-04"/>
    </inertial>
  </link>
  <gazebo reference="gripper_soft_robotics_gripper_base_link">
    <material>Gazebo/Grey</material>
  </gazebo>
  <gazebo reference="gripper_soft_robotics_left_finger_link1">
    <material>Gazebo/Blue</material>
  </gazebo>
  <gazebo reference="gripper_soft_robotics_right_finger_link1">
    <material>Gazebo/Blue</material>
  </gazebo>
  <gazebo reference="gripper_soft_robotics_left_finger_link2">
    <material>Gazebo/Blue</material>
  </gazebo>
  <gazebo reference="gripper_soft_robotics_right_finger_link2">
    <material>Gazebo/Blue</material>
  </gazebo>
  <ros2_control name="gripper" type="system">
    <hardware>
      <plugin>gazebo_ros2_control/GazeboSystem</plugin>
    </hardware>
    <joint name="gripper_soft_robotics_gripper_left_finger_joint1">
      <command_interface name="position"/>
      <command_interface name="velocity"/>
      <state_interface name="position">
        <!-- initial position for the mock system and simulation -->
        <param name="initial_value">0.0</param>
      </state_interface>
      <state_interface name="velocity">
        <param name="initial_value">0.0</param>
      </state_interface>
      <state_interface name="effort">
        <param name="initial_value">0.0</param>
      </state_interface>
    </joint>
    <joint name="gripper_soft_robotics_gripper_right_finger_joint1">
      <command_interface name="position"/>
      <command_interface name="velocity"/>
      <state_interface name="position">
        <!-- initial position for the mock system and simulation -->
        <param name="initial_value">0.0</param>
      </state_interface>
      <state_interface name="velocity">
        <param name="initial_value">0.0</param>
      </state_interface>
      <state_interface name="effort">
        <param name="initial_value">0.0</param>
      </state_interface>
    </joint>
  </ros2_control>
  <!-- TRANSMISSION -->
  <transmission name="gripper_right_finger_trans">
    <type>transmission_interface/SimpleTransmission</type>
    <joint name="gripper_soft_robotics_gripper_left_finger_joint1">
      <hardwareInterface>hardware_interface/PositionJointInterface</hardwareInterface>
    </joint>
    <actuator name="gripper_right_finger_motor">
      <mechanicalReduction>1</mechanicalReduction>
    </actuator>
  </transmission>
  <transmission name="gripper_left_finger_trans">
    <type>transmission_interface/SimpleTransmission</type>
    <joint name="gripper_soft_robotics_gripper_right_finger_joint1">
      <hardwareInterface>hardware_interface/PositionJointInterface</hardwareInterface>
    </joint>
    <actuator name="gripper_shoulder_lift_motor">
      <mechanicalReduction>1</mechanicalReduction>
    </actuator>
  </transmission>
  <ros2_control name="GazeboSystem" type="system">
    <hardware>
      <plugin>gazebo_ros2_control/GazeboSystem</plugin>
    </hardware>
    <joint name="left_wheel_joint">
      <command_interface name="velocity">
        <param name="min">-1</param>
        <param name="max">1</param>
      </command_interface>
      <state_interface name="position"/>
      <state_interface name="velocity"/>
    </joint>
    <joint name="right_wheel_joint">
      <command_interface name="velocity">
        <param name="min">-1</param>
        <param name="max">1</param>
      </command_interface>
      <state_interface name="position"/>
      <state_interface name="velocity"/>
    </joint>
    <joint name="fl_caster_rotation_joint">
      <state_interface name="position"/>
      <state_interface name="velocity"/>
    </joint>
    <joint name="fr_caster_rotation_joint">
      <state_interface name="position"/>
      <state_interface name="velocity"/>
    </joint>
    <joint name="bl_caster_rotation_joint">
      <state_interface name="position"/>
      <state_interface name="velocity"/>
    </joint>
    <joint name="br_caster_rotation_joint">
      <state_interface name="position"/>
      <state_interface name="velocity"/>
    </joint>
    <joint name="fl_caster_wheel_joint">
      <state_interface name="position"/>
      <state_interface name="velocity"/>
    </joint>
    <joint name="fr_caster_wheel_joint">
      <state_interface name="position"/>
      <state_interface name="velocity"/>
    </joint>
    <joint name="bl_caster_wheel_joint">
      <state_interface name="position"/>
      <state_interface name="velocity"/>
    </joint>
    <joint name="br_caster_wheel_joint">
      <state_interface name="position"/>
      <state_interface name="velocity"/>
    </joint>
  </ros2_control>
  <gazebo>
    <!-- Joint state publisher -->
    <plugin filename="libgazebo_ros2_control.so" name="gazebo_ros2_control">
      <parameters>/home/dikki/ros2_ws_simulation/install/mir_description/share/mir_description/config/diffdrive_controller_combined.yaml</parameters>
    </plugin>
  </gazebo>
</robot>
