<sdf version='1.7'>
  <world name='maze_world'>
    <light name='sun' type='directional'>
      <cast_shadows>1</cast_shadows>
      <pose>0 0 10 0 -0 0</pose>
      <diffuse>0.8 0.8 0.8 1</diffuse>
      <specular>0.2 0.2 0.2 1</specular>
      <attenuation>
        <range>1000</range>
        <constant>0.9</constant>
        <linear>0.01</linear>
        <quadratic>0.001</quadratic>
      </attenuation>
      <direction>-0.5 0.1 -0.9</direction>
      <spot>
        <inner_angle>0</inner_angle>
        <outer_angle>0</outer_angle>
        <falloff>0</falloff>
      </spot>
    </light>
    <model name='ground_plane'>
      <static>1</static>
      <link name='link'>
        <collision name='collision'>
          <geometry>
            <plane>
              <normal>0 0 1</normal>
              <size>100 100</size>
            </plane>
          </geometry>
          <surface>
            <friction>
              <ode>
                <mu>100</mu>
                <mu2>50</mu2>
              </ode>
              <torsional>
                <ode/>
              </torsional>
            </friction>
            <contact>
              <ode/>
            </contact>
            <bounce/>
          </surface>
          <max_contacts>10</max_contacts>
        </collision>
        <visual name='visual'>
          <cast_shadows>0</cast_shadows>
          <geometry>
            <plane>
              <normal>0 0 1</normal>
              <size>100 100</size>
            </plane>
          </geometry>
          <material>
            <script>
              <uri>file://media/materials/scripts/gazebo.material</uri>
              <name>Gazebo/Grey</name>
            </script>
          </material>
        </visual>
        <self_collide>0</self_collide>
        <enable_wind>0</enable_wind>
        <kinematic>0</kinematic>
      </link>
    </model>
    <model name='maze'>
      <pose>-0.078283 0.098984 0 0 -0 0</pose>
      <link name='Wall_0'>
        <collision name='Wall_0_Collision'>
          <geometry>
            <box>
              <size>20 0.15 2.5</size>
            </box>
          </geometry>
          <pose>0 0 1.25 0 -0 0</pose>
          <max_contacts>10</max_contacts>
          <surface>
            <contact>
              <ode/>
            </contact>
            <bounce/>
            <friction>
              <torsional>
                <ode/>
              </torsional>
              <ode/>
            </friction>
          </surface>
        </collision>
        <visual name='Wall_0_Visual'>
          <pose>0 0 1.25 0 -0 0</pose>
          <geometry>
            <box>
              <size>20 0.15 2.5</size>
            </box>
          </geometry>
          <material>
            <script>
              <uri>file://media/materials/scripts/gazebo.material</uri>
              <name>Gazebo/Grey</name>
            </script>
            <ambient>1 1 1 1</ambient>
          </material>
        </visual>
        <pose>0.030536 9.925 0 0 -0 0</pose>
        <self_collide>0</self_collide>
        <enable_wind>0</enable_wind>
        <kinematic>0</kinematic>
      </link>
      <link name='Wall_1'>
        <collision name='Wall_1_Collision'>
          <geometry>
            <box>
              <size>20 0.15 2.5</size>
            </box>
          </geometry>
          <pose>0 0 1.25 0 -0 0</pose>
          <max_contacts>10</max_contacts>
          <surface>
            <contact>
              <ode/>
            </contact>
            <bounce/>
            <friction>
              <torsional>
                <ode/>
              </torsional>
              <ode/>
            </friction>
          </surface>
        </collision>
        <visual name='Wall_1_Visual'>
          <pose>0 0 1.25 0 -0 0</pose>
          <geometry>
            <box>
              <size>20 0.15 2.5</size>
            </box>
          </geometry>
          <material>
            <script>
              <uri>file://media/materials/scripts/gazebo.material</uri>
              <name>Gazebo/Grey</name>
            </script>
            <ambient>1 1 1 1</ambient>
          </material>
        </visual>
        <pose>9.95554 0 0 0 0 -1.5708</pose>
        <self_collide>0</self_collide>
        <enable_wind>0</enable_wind>
        <kinematic>0</kinematic>
      </link>
      <link name='Wall_2'>
        <collision name='Wall_2_Collision'>
          <geometry>
            <box>
              <size>20 0.15 2.5</size>
            </box>
          </geometry>
          <pose>0 0 1.25 0 -0 0</pose>
          <max_contacts>10</max_contacts>
          <surface>
            <contact>
              <ode/>
            </contact>
            <bounce/>
            <friction>
              <torsional>
                <ode/>
              </torsional>
              <ode/>
            </friction>
          </surface>
        </collision>
        <visual name='Wall_2_Visual'>
          <pose>0 0 1.25 0 -0 0</pose>
          <geometry>
            <box>
              <size>20 0.15 2.5</size>
            </box>
          </geometry>
          <material>
            <script>
              <uri>file://media/materials/scripts/gazebo.material</uri>
              <name>Gazebo/Grey</name>
            </script>
            <ambient>1 1 1 1</ambient>
          </material>
        </visual>
        <pose>0.030536 -9.925 0 0 -0 3.14159</pose>
        <self_collide>0</self_collide>
        <enable_wind>0</enable_wind>
        <kinematic>0</kinematic>
      </link>
      <link name='Wall_24'>
        <collision name='Wall_24_Collision'>
          <geometry>
            <box>
              <size>1.5 0.15 2.5</size>
            </box>
          </geometry>
          <pose>0 0 1.25 0 -0 0</pose>
          <max_contacts>10</max_contacts>
          <surface>
            <contact>
              <ode/>
            </contact>
            <bounce/>
            <friction>
              <torsional>
                <ode/>
              </torsional>
              <ode/>
            </friction>
          </surface>
        </collision>
        <visual name='Wall_24_Visual'>
          <pose>0 0 1.25 0 -0 0</pose>
          <geometry>
            <box>
              <size>1.5 0.15 2.5</size>
            </box>
          </geometry>
          <material>
            <script>
              <uri>file://media/materials/scripts/gazebo.material</uri>
              <name>Gazebo/Grey</name>
            </script>
            <ambient>1 1 1 1</ambient>
          </material>
        </visual>
        <pose>5.35089 3.21906 0 0 -0 3.14159</pose>
        <self_collide>0</self_collide>
        <enable_wind>0</enable_wind>
        <kinematic>0</kinematic>
      </link>
      <link name='Wall_25'>
        <collision name='Wall_25_Collision'>
          <geometry>
            <box>
              <size>5.25 0.15 2.5</size>
            </box>
          </geometry>
          <pose>0 0 1.25 0 -0 0</pose>
          <max_contacts>10</max_contacts>
          <surface>
            <contact>
              <ode/>
            </contact>
            <bounce/>
            <friction>
              <torsional>
                <ode/>
              </torsional>
              <ode/>
            </friction>
          </surface>
        </collision>
        <visual name='Wall_25_Visual'>
          <pose>0 0 1.25 0 -0 0</pose>
          <geometry>
            <box>
              <size>5.25 0.15 2.5</size>
            </box>
          </geometry>
          <material>
            <script>
              <uri>file://media/materials/scripts/gazebo.material</uri>
              <name>Gazebo/Grey</name>
            </script>
            <ambient>1 1 1 1</ambient>
          </material>
        </visual>
        <pose>4.67589 5.76906 0 0 -0 1.5708</pose>
        <self_collide>0</self_collide>
        <enable_wind>0</enable_wind>
        <kinematic>0</kinematic>
      </link>
      <link name='Wall_27'>
        <collision name='Wall_27_Collision'>
          <geometry>
            <box>
              <size>5.5 0.15 2.5</size>
            </box>
          </geometry>
          <pose>0 0 1.25 0 -0 0</pose>
          <max_contacts>10</max_contacts>
          <surface>
            <contact>
              <ode/>
            </contact>
            <bounce/>
            <friction>
              <torsional>
                <ode/>
              </torsional>
              <ode/>
            </friction>
          </surface>
        </collision>
        <visual name='Wall_27_Visual'>
          <pose>0 0 1.25 0 -0 0</pose>
          <geometry>
            <box>
              <size>5.5 0.15 2.5</size>
            </box>
          </geometry>
          <material>
            <script>
              <uri>file://media/materials/scripts/gazebo.material</uri>
              <name>Gazebo/Grey</name>
            </script>
            <ambient>1 1 1 1</ambient>
          </material>
        </visual>
        <pose>7.10914 4.73454 0 0 0 -1.5708</pose>
        <self_collide>0</self_collide>
        <enable_wind>0</enable_wind>
        <kinematic>0</kinematic>
      </link>
      <link name='Wall_28'>
        <collision name='Wall_28_Collision'>
          <geometry>
            <box>
              <size>3 0.15 2.5</size>
            </box>
          </geometry>
          <pose>0 0 1.25 0 -0 0</pose>
          <max_contacts>10</max_contacts>
          <surface>
            <contact>
              <ode/>
            </contact>
            <bounce/>
            <friction>
              <torsional>
                <ode/>
              </torsional>
              <ode/>
            </friction>
          </surface>
        </collision>
        <visual name='Wall_28_Visual'>
          <pose>0 0 1.25 0 -0 0</pose>
          <geometry>
            <box>
              <size>3 0.15 2.5</size>
            </box>
          </geometry>
          <material>
            <script>
              <uri>file://media/materials/scripts/gazebo.material</uri>
              <name>Gazebo/Grey</name>
            </script>
            <ambient>1 1 1 1</ambient>
          </material>
        </visual>
        <pose>8.53414 2.05954 0 0 -0 0</pose>
        <self_collide>0</self_collide>
        <enable_wind>0</enable_wind>
        <kinematic>0</kinematic>
      </link>
      <link name='Wall_3'>
        <collision name='Wall_3_Collision'>
          <geometry>
            <box>
              <size>20 0.15 2.5</size>
            </box>
          </geometry>
          <pose>0 0 1.25 0 -0 0</pose>
          <max_contacts>10</max_contacts>
          <surface>
            <contact>
              <ode/>
            </contact>
            <bounce/>
            <friction>
              <torsional>
                <ode/>
              </torsional>
              <ode/>
            </friction>
          </surface>
        </collision>
        <visual name='Wall_3_Visual'>
          <pose>0 0 1.25 0 -0 0</pose>
          <geometry>
            <box>
              <size>20 0.15 2.5</size>
            </box>
          </geometry>
          <material>
            <script>
              <uri>file://media/materials/scripts/gazebo.material</uri>
              <name>Gazebo/Grey</name>
            </script>
            <ambient>1 1 1 1</ambient>
          </material>
        </visual>
        <pose>-9.89446 0 0 0 -0 1.5708</pose>
        <self_collide>0</self_collide>
        <enable_wind>0</enable_wind>
        <kinematic>0</kinematic>
      </link>
      <link name='Wall_30'>
        <collision name='Wall_30_Collision'>
          <geometry>
            <box>
              <size>5.5 0.15 2.5</size>
            </box>
          </geometry>
          <pose>0 0 1.25 0 -0 0</pose>
          <max_contacts>10</max_contacts>
          <surface>
            <contact>
              <ode/>
            </contact>
            <bounce/>
            <friction>
              <torsional>
                <ode/>
              </torsional>
              <ode/>
            </friction>
          </surface>
        </collision>
        <visual name='Wall_30_Visual'>
          <pose>0 0 1.25 0 -0 0</pose>
          <geometry>
            <box>
              <size>5.5 0.15 2.5</size>
            </box>
          </geometry>
          <material>
            <script>
              <uri>file://media/materials/scripts/gazebo.material</uri>
              <name>Gazebo/Grey</name>
            </script>
            <ambient>1 1 1 1</ambient>
          </material>
        </visual>
        <pose>-4.35914 -2.82889 0 0 0 -1.5708</pose>
        <self_collide>0</self_collide>
        <enable_wind>0</enable_wind>
        <kinematic>0</kinematic>
      </link>
      <link name='Wall_31'>
        <collision name='Wall_31_Collision'>
          <geometry>
            <box>
              <size>5.75 0.15 2.5</size>
            </box>
          </geometry>
          <pose>0 0 1.25 0 -0 0</pose>
          <max_contacts>10</max_contacts>
          <surface>
            <contact>
              <ode/>
            </contact>
            <bounce/>
            <friction>
              <torsional>
                <ode/>
              </torsional>
              <ode/>
            </friction>
          </surface>
        </collision>
        <visual name='Wall_31_Visual'>
          <pose>0 0 1.25 0 -0 0</pose>
          <geometry>
            <box>
              <size>5.75 0.15 2.5</size>
            </box>
          </geometry>
          <material>
            <script>
              <uri>file://media/materials/scripts/gazebo.material</uri>
              <name>Gazebo/Grey</name>
            </script>
            <ambient>1 1 1 1</ambient>
          </material>
        </visual>
        <pose>-7.15914 -5.50389 0 0 -0 3.14159</pose>
        <self_collide>0</self_collide>
        <enable_wind>0</enable_wind>
        <kinematic>0</kinematic>
      </link>
      <link name='Wall_5'>
        <collision name='Wall_5_Collision'>
          <geometry>
            <box>
              <size>16 0.15 2.5</size>
            </box>
          </geometry>
          <pose>0 0 1.25 0 -0 0</pose>
          <max_contacts>10</max_contacts>
          <surface>
            <contact>
              <ode/>
            </contact>
            <bounce/>
            <friction>
              <torsional>
                <ode/>
              </torsional>
              <ode/>
            </friction>
          </surface>
        </collision>
        <visual name='Wall_5_Visual'>
          <pose>0 0 1.25 0 -0 0</pose>
          <geometry>
            <box>
              <size>16 0.15 2.5</size>
            </box>
          </geometry>
          <material>
            <script>
              <uri>file://media/materials/scripts/gazebo.material</uri>
              <name>Gazebo/Grey</name>
            </script>
            <ambient>1 1 1 1</ambient>
          </material>
        </visual>
        <pose>-1.89911 1.86906 0 0 -0 0</pose>
        <self_collide>0</self_collide>
        <enable_wind>0</enable_wind>
        <kinematic>0</kinematic>
      </link>
      <link name='Wall_6'>
        <collision name='Wall_6_Collision'>
          <geometry>
            <box>
              <size>1.5 0.15 2.5</size>
            </box>
          </geometry>
          <pose>0 0 1.25 0 -0 0</pose>
          <max_contacts>10</max_contacts>
          <surface>
            <contact>
              <ode/>
            </contact>
            <bounce/>
            <friction>
              <torsional>
                <ode/>
              </torsional>
              <ode/>
            </friction>
          </surface>
        </collision>
        <visual name='Wall_6_Visual'>
          <pose>0 0 1.25 0 -0 0</pose>
          <geometry>
            <box>
              <size>1.5 0.15 2.5</size>
            </box>
          </geometry>
          <material>
            <script>
              <uri>file://media/materials/scripts/gazebo.material</uri>
              <name>Gazebo/Grey</name>
            </script>
            <ambient>1 1 1 1</ambient>
          </material>
        </visual>
        <pose>6.02589 2.54406 0 0 -0 1.5708</pose>
        <self_collide>0</self_collide>
        <enable_wind>0</enable_wind>
        <kinematic>0</kinematic>
      </link>
      <link name='Wall_8'>
        <collision name='Wall_8_Collision'>
          <geometry>
            <box>
              <size>0.15 0.15 2.5</size>
            </box>
          </geometry>
          <pose>0 0 1.25 0 -0 0</pose>
          <max_contacts>10</max_contacts>
          <surface>
            <contact>
              <ode/>
            </contact>
            <bounce/>
            <friction>
              <torsional>
                <ode/>
              </torsional>
              <ode/>
            </friction>
          </surface>
        </collision>
        <visual name='Wall_8_Visual'>
          <pose>0 0 1.25 0 -0 0</pose>
          <geometry>
            <box>
              <size>0.15 0.15 2.5</size>
            </box>
          </geometry>
          <material>
            <script>
              <uri>file://media/materials/scripts/gazebo.material</uri>
              <name>Gazebo/Grey</name>
            </script>
            <ambient>1 1 1 1</ambient>
          </material>
        </visual>
        <pose>6.02589 3.21906 0 0 -0 0</pose>
        <self_collide>0</self_collide>
        <enable_wind>0</enable_wind>
        <kinematic>0</kinematic>
      </link>
      <static>1</static>
    </model>
    <model name='manipulation_test_box_with_aruco'>
      <pose>6.5 0.5 0.25 0 -0 0</pose>
      <static>0</static>
      <link name='box_link'>
        <collision name='collision'>
          <geometry>
            <box>
              <size>0.5 2 0.5</size>
            </box>
          </geometry>
          <surface>
            <friction>
              <ode>
                <mu>0.1</mu>
                <mu2>0.1</mu2>
              </ode>
              <torsional>
                <ode/>
              </torsional>
            </friction>
            <contact>
              <ode/>
            </contact>
            <bounce/>
          </surface>
          <max_contacts>10</max_contacts>
        </collision>
        <visual name='visual'>
          <geometry>
            <box>
              <size>0.5 2 0.5</size>
            </box>
          </geometry>
          <material>
            <ambient>0.8 0.2 0.2 1</ambient>
            <diffuse>0.8 0.2 0.2 1</diffuse>
            <specular>0.1 0.1 0.1 1</specular>
          </material>
        </visual>
        <inertial>
          <mass>0.2</mass>
          <inertia>
            <ixx>0.02</ixx>
            <iyy>0.02</iyy>
            <izz>0.02</izz>
            <ixy>0</ixy>
            <ixz>0</ixz>
            <iyz>0</iyz>
          </inertia>
          <pose>0 0 0 0 -0 0</pose>
        </inertial>
        <self_collide>0</self_collide>
        <enable_wind>0</enable_wind>
        <kinematic>0</kinematic>
      </link>
      <frame name='box_marker::__model__' attached_to='box_marker::link'>
        <pose relative_to='__model__'>-0.25 0 -0.25 0 -0 0</pose>
      </frame>
      <static>1</static>
      <link name='box_marker::link'>
        <visual name='visual'>
          <geometry>
            <mesh>
              <uri>model://marker_0/meshes/marker_0.dae</uri>
              <scale>1 1 1</scale>
            </mesh>
          </geometry>
        </visual>
        <pose relative_to='box_marker::__model__'>0 0 0 0 -0 0</pose>
        <self_collide>0</self_collide>
        <inertial>
          <pose>0 0 0 0 -0 0</pose>
          <inertia>
            <ixx>1</ixx>
            <ixy>0</ixy>
            <ixz>0</ixz>
            <iyy>1</iyy>
            <iyz>0</iyz>
            <izz>1</izz>
          </inertia>
          <mass>1</mass>
        </inertial>
        <enable_wind>0</enable_wind>
        <kinematic>0</kinematic>
      </link>
      <joint name='marker_joint' type='fixed'>
        <parent>box_link</parent>
        <child>box_marker::link</child>
      </joint>
    </model>
    <model name='manipulation_test_box_2'>
      <pose>4.64 9.15 0.25 0 -0 0</pose>
      <static>0</static>
      <link name='link'>
        <collision name='collision'>
          <geometry>
            <box>
              <size>0.25 0.25 0.25</size>
            </box>
          </geometry>
          <surface>
            <friction>
              <ode>
                <mu>0.1</mu>
                <mu2>0.1</mu2>
              </ode>
              <torsional>
                <ode/>
              </torsional>
            </friction>
            <contact>
              <ode/>
            </contact>
            <bounce/>
          </surface>
          <max_contacts>10</max_contacts>
        </collision>
        <visual name='visual'>
          <geometry>
            <box>
              <size>0.25 0.25 0.25</size>
            </box>
          </geometry>
          <material>
            <ambient>0.8 0.2 0.2 1</ambient>
            <diffuse>0.8 0.2 0.2 1</diffuse>
            <specular>0.1 0.1 0.1 1</specular>
          </material>
        </visual>
        <inertial>
          <mass>0.2</mass>
          <inertia>
            <ixx>0.02</ixx>
            <iyy>0.02</iyy>
            <izz>0.02</izz>
            <ixy>0</ixy>
            <ixz>0</ixz>
            <iyz>0</iyz>
          </inertia>
          <pose>0 0 0 0 -0 0</pose>
        </inertial>
        <self_collide>0</self_collide>
        <enable_wind>0</enable_wind>
        <kinematic>0</kinematic>
      </link>
    </model>
    <model name='detection_test_box_2'>
      <pose>1.45 -0.139 0.25 0 -0 0</pose>
      <static>0</static>
      <link name='link'>
        <collision name='collision'>
          <geometry>
            <box>
              <size>0.25 0.25 0.25</size>
            </box>
          </geometry>
          <surface>
            <friction>
              <ode>
                <mu>0.1</mu>
                <mu2>0.1</mu2>
              </ode>
              <torsional>
                <ode/>
              </torsional>
            </friction>
            <contact>
              <ode/>
            </contact>
            <bounce/>
          </surface>
          <max_contacts>10</max_contacts>
        </collision>
        <visual name='visual'>
          <geometry>
            <box>
              <size>0.25 0.25 0.25</size>
            </box>
          </geometry>
          <material>
            <ambient>0.8 0.2 0.2 1</ambient>
            <diffuse>0.8 0.2 0.2 1</diffuse>
            <specular>0.1 0.1 0.1 1</specular>
          </material>
        </visual>
        <inertial>
          <mass>0.2</mass>
          <inertia>
            <ixx>0.02</ixx>
            <iyy>0.02</iyy>
            <izz>0.02</izz>
            <ixy>0</ixy>
            <ixz>0</ixz>
            <iyz>0</iyz>
          </inertia>
          <pose>0 0 0 0 -0 0</pose>
        </inertial>
        <self_collide>0</self_collide>
        <enable_wind>0</enable_wind>
        <kinematic>0</kinematic>
      </link>
    </model>
    <gravity>0 0 -9.8</gravity>
    <magnetic_field>6e-06 2.3e-05 -4.2e-05</magnetic_field>
    <atmosphere type='adiabatic'/>
    <physics type='ode'>
      <max_step_size>0.001</max_step_size>
      <real_time_factor>1</real_time_factor>
      <real_time_update_rate>1000</real_time_update_rate>
    </physics>
    <scene>
      <ambient>0.4 0.4 0.4 1</ambient>
      <background>0.7 0.7 0.7 1</background>
      <shadows>1</shadows>
    </scene>
    <audio>
      <device>default</device>
    </audio>
    <wind/>
    <spherical_coordinates>
      <surface_model>EARTH_WGS84</surface_model>
      <latitude_deg>0</latitude_deg>
      <longitude_deg>0</longitude_deg>
      <elevation>0</elevation>
      <heading_deg>0</heading_deg>
    </spherical_coordinates>
    <model name='mir_robot'>
      <link name='base_footprint'>
        <inertial>
          <pose>-0.040575 0 0.186762 0 -0 0</pose>
          <mass>267.9</mass>
          <inertia>
            <ixx>4.20681</ixx>
            <ixy>-0.261272</ixy>
            <ixz>-0.416885</ixz>
            <iyy>8.10916</iyy>
            <iyz>0</iyz>
            <izz>8.21514</izz>
          </inertia>
        </inertial>
        <collision name='base_footprint_fixed_joint_lump__base_link_collision'>
          <pose>-0.004485 0 0 0 -0 0</pose>
          <geometry>
            <mesh>
              <scale>1 1 1</scale>
              <uri>model://mir_description/meshes/collision/mir_250_base.stl</uri>
            </mesh>
          </geometry>
          <surface>
            <contact>
              <ode/>
            </contact>
            <friction>
              <ode/>
              <torsional>
                <ode/>
              </torsional>
            </friction>
            <bounce/>
          </surface>
          <max_contacts>10</max_contacts>
        </collision>
        <collision name='base_footprint_fixed_joint_lump__back_laser_link_collision_1'>
          <pose>-0.3164 -0.2064 0.1914 3.14159 -0 -2.35619</pose>
          <geometry>
            <mesh>
              <scale>1 1 1</scale>
              <uri>model://mir_description/meshes/visual/sick_lms-100.stl</uri>
            </mesh>
          </geometry>
          <surface>
            <contact>
              <ode/>
            </contact>
            <friction>
              <ode/>
              <torsional>
                <ode/>
              </torsional>
            </friction>
            <bounce/>
          </surface>
          <max_contacts>10</max_contacts>
        </collision>
        <collision name='base_footprint_fixed_joint_lump__front_laser_link_collision_2'>
          <pose>0.3164 0.2064 0.1914 3.14159 -0 0.785398</pose>
          <geometry>
            <mesh>
              <scale>1 1 1</scale>
              <uri>model://mir_description/meshes/visual/sick_lms-100.stl</uri>
            </mesh>
          </geometry>
          <surface>
            <contact>
              <ode/>
            </contact>
            <friction>
              <ode/>
              <torsional>
                <ode/>
              </torsional>
            </friction>
            <bounce/>
          </surface>
          <max_contacts>10</max_contacts>
        </collision>
        <collision name='base_footprint_fixed_joint_lump__power_unit_collision_3'>
          <pose>0 0 0.545 0 -0 0</pose>
          <geometry>
            <box>
              <size>0.73 0.56 0.49</size>
            </box>
          </geometry>
          <max_contacts>10</max_contacts>
          <surface>
            <contact>
              <ode/>
            </contact>
            <bounce/>
            <friction>
              <torsional>
                <ode/>
              </torsional>
              <ode/>
            </friction>
          </surface>
        </collision>
        <collision name='base_footprint_fixed_joint_lump__ur_base_link_inertia_collision_4'>
          <pose>0.135 0 0.79 0 0 -1.5708</pose>
          <geometry>
            <mesh>
              <scale>1 1 1</scale>
              <uri>file:///home/dikki/ros2_ws_simulation/install/ur_description/share/ur_description/meshes/ur5e/collision/base.stl</uri>
            </mesh>
          </geometry>
          <max_contacts>10</max_contacts>
          <surface>
            <contact>
              <ode/>
            </contact>
            <bounce/>
            <friction>
              <torsional>
                <ode/>
              </torsional>
              <ode/>
            </friction>
          </surface>
        </collision>
        <visual name='base_footprint_fixed_joint_lump__base_link_visual'>
          <pose>-0.004485 0 0 0 -0 0</pose>
          <geometry>
            <mesh>
              <scale>1 1 1</scale>
              <uri>model://mir_description/meshes/visual/mir_250_base.stl</uri>
            </mesh>
          </geometry>
          <material>
            <script>
              <name>Gazebo/Grey</name>
              <uri>file://media/materials/scripts/gazebo.material</uri>
            </script>
          </material>
        </visual>
        <visual name='base_footprint_fixed_joint_lump__back_laser_link_visual_1'>
          <pose>-0.3164 -0.2064 0.1914 3.14159 -0 -2.35619</pose>
          <geometry>
            <mesh>
              <scale>1 1 1</scale>
              <uri>model://mir_description/meshes/visual/sick_lms-100.stl</uri>
            </mesh>
          </geometry>
          <material>
            <script>
              <name>Gazebo/FlatBlack</name>
              <uri>file://media/materials/scripts/gazebo.material</uri>
            </script>
          </material>
        </visual>
        <visual name='base_footprint_fixed_joint_lump__front_laser_link_visual_2'>
          <pose>0.3164 0.2064 0.1914 3.14159 -0 0.785398</pose>
          <geometry>
            <mesh>
              <scale>1 1 1</scale>
              <uri>model://mir_description/meshes/visual/sick_lms-100.stl</uri>
            </mesh>
          </geometry>
          <material>
            <script>
              <name>Gazebo/FlatBlack</name>
              <uri>file://media/materials/scripts/gazebo.material</uri>
            </script>
          </material>
        </visual>
        <visual name='base_footprint_fixed_joint_lump__power_unit_visual_3'>
          <pose>0 0 0.545 0 -0 0</pose>
          <geometry>
            <box>
              <size>0.73 0.56 0.49</size>
            </box>
          </geometry>
        </visual>
        <visual name='base_footprint_fixed_joint_lump__ur_base_link_inertia_visual_4'>
          <pose>0.135 0 0.79 0 0 -1.5708</pose>
          <geometry>
            <mesh>
              <scale>1 1 1</scale>
              <uri>file:///home/dikki/ros2_ws_simulation/install/ur_description/share/ur_description/meshes/ur5e/visual/base.dae</uri>
            </mesh>
          </geometry>
        </visual>
        <sensor name='back_laser_link' type='ray'>
          <visualize>0</visualize>
          <update_rate>12.5</update_rate>
          <ray>
            <scan>
              <horizontal>
                <samples>541</samples>
                <resolution>1</resolution>
                <min_angle>-2.09438</min_angle>
                <max_angle>2.09438</max_angle>
              </horizontal>
              <vertical>
                <samples>1</samples>
                <min_angle>0</min_angle>
                <max_angle>0</max_angle>
              </vertical>
            </scan>
            <range>
              <min>0.05</min>
              <max>29</max>
              <resolution>0.01</resolution>
            </range>
            <noise>
              <type>gaussian</type>
              <mean>0</mean>
              <stddev>0.01</stddev>
            </noise>
          </ray>
          <plugin name='gazebo_ros_back_laser_link_controller' filename='libgazebo_ros_ray_sensor.so'>
            <ros>
              <remapping>~/out:=b_scan</remapping>
            </ros>
            <output_type>sensor_msgs/LaserScan</output_type>
            <frame_name>back_laser_link</frame_name>
          </plugin>
          <pose>-0.3164 -0.2064 0.1914 0 0 -2.35619</pose>
        </sensor>
        <sensor name='front_laser_link' type='ray'>
          <visualize>0</visualize>
          <update_rate>12.5</update_rate>
          <ray>
            <scan>
              <horizontal>
                <samples>541</samples>
                <resolution>1</resolution>
                <min_angle>-2.09438</min_angle>
                <max_angle>2.09438</max_angle>
              </horizontal>
              <vertical>
                <samples>1</samples>
                <min_angle>0</min_angle>
                <max_angle>0</max_angle>
              </vertical>
            </scan>
            <range>
              <min>0.05</min>
              <max>29</max>
              <resolution>0.01</resolution>
            </range>
            <noise>
              <type>gaussian</type>
              <mean>0</mean>
              <stddev>0.01</stddev>
            </noise>
          </ray>
          <plugin name='gazebo_ros_front_laser_link_controller' filename='libgazebo_ros_ray_sensor.so'>
            <ros>
              <remapping>~/out:=f_scan</remapping>
            </ros>
            <output_type>sensor_msgs/LaserScan</output_type>
            <frame_name>front_laser_link</frame_name>
          </plugin>
          <pose>0.3164 0.2064 0.1914 0 -0 0.785398</pose>
        </sensor>
        <gravity>1</gravity>
        <sensor name='imu_sensor' type='imu'>
          <always_on>1</always_on>
          <update_rate>50</update_rate>
          <visualize>1</visualize>
          <imu>
            <angular_velocity>
              <x>
                <noise type='gaussian'>
                  <mean>0</mean>
                  <stddev>0.00017</stddev>
                  <bias_mean>7.5e-06</bias_mean>
                  <bias_stddev>8e-07</bias_stddev>
                </noise>
              </x>
              <y>
                <noise type='gaussian'>
                  <mean>0</mean>
                  <stddev>0.00017</stddev>
                  <bias_mean>7.5e-06</bias_mean>
                  <bias_stddev>8e-07</bias_stddev>
                </noise>
              </y>
              <z>
                <noise type='gaussian'>
                  <mean>0</mean>
                  <stddev>0.00017</stddev>
                  <bias_mean>7.5e-06</bias_mean>
                  <bias_stddev>8e-07</bias_stddev>
                </noise>
              </z>
            </angular_velocity>
            <linear_acceleration>
              <x>
                <noise type='gaussian'>
                  <mean>0</mean>
                  <stddev>0.00017</stddev>
                  <bias_mean>0.1</bias_mean>
                  <bias_stddev>0.001</bias_stddev>
                </noise>
              </x>
              <y>
                <noise type='gaussian'>
                  <mean>0</mean>
                  <stddev>0.00017</stddev>
                  <bias_mean>0.1</bias_mean>
                  <bias_stddev>0.001</bias_stddev>
                </noise>
              </y>
              <z>
                <noise type='gaussian'>
                  <mean>0</mean>
                  <stddev>0.00017</stddev>
                  <bias_mean>0.1</bias_mean>
                  <bias_stddev>0.001</bias_stddev>
                </noise>
              </z>
            </linear_acceleration>
          </imu>
          <plugin name='imu_plugin' filename='libgazebo_ros_imu_sensor.so'>
            <initial_orientation_as_reference>0</initial_orientation_as_reference>
            <ros>
              <namespace>imu_data</namespace>
              <remapping>~/out:=data</remapping>
              <frame_name>imu_frame</frame_name>
            </ros>
          </plugin>
          <pose>0 0 0.25 0 -0 0</pose>
        </sensor>
        <self_collide>0</self_collide>
        <enable_wind>0</enable_wind>
        <kinematic>0</kinematic>
      </link>
      <joint name='bl_caster_rotation_joint' type='revolute'>
        <pose relative_to='base_footprint'>-0.296 0.188 0.1565 0 -0 0</pose>
        <parent>base_footprint</parent>
        <child>bl_caster_rotation_link</child>
        <axis>
          <xyz>0 0 1</xyz>
          <limit>
            <lower>-1e+16</lower>
            <upper>1e+16</upper>
          </limit>
          <dynamics>
            <damping>0</damping>
            <friction>0</friction>
            <spring_reference>0</spring_reference>
            <spring_stiffness>0</spring_stiffness>
          </dynamics>
        </axis>
      </joint>
      <link name='bl_caster_rotation_link'>
        <pose relative_to='bl_caster_rotation_joint'>0 0 0 0 -0 0</pose>
        <inertial>
          <pose>0 0 -0.0425 0.418879 0 1.5708</pose>
          <mass>0.309754</mass>
          <inertia>
            <ixx>0.000584452</ixx>
            <ixy>0</ixy>
            <ixz>0</ixz>
            <iyy>0.000528726</iyy>
            <iyz>0</iyz>
            <izz>0.000179236</izz>
          </inertia>
        </inertial>
        <collision name='bl_caster_rotation_link_collision'>
          <pose>0 0 0 0 -0 0</pose>
          <geometry>
            <mesh>
              <scale>1 1 1</scale>
              <uri>model://mir_description/meshes/collision/caster_wheel_base.stl</uri>
            </mesh>
          </geometry>
          <surface>
            <contact>
              <ode/>
            </contact>
            <friction>
              <ode/>
              <torsional>
                <ode/>
              </torsional>
            </friction>
            <bounce/>
          </surface>
          <max_contacts>10</max_contacts>
        </collision>
        <visual name='bl_caster_rotation_link_visual'>
          <pose>0 0 0 0 -0 0</pose>
          <geometry>
            <mesh>
              <scale>1 1 1</scale>
              <uri>model://mir_description/meshes/visual/caster_wheel_base.stl</uri>
            </mesh>
          </geometry>
          <material>
            <script>
              <name>Gazebo/Grey</name>
              <uri>file://media/materials/scripts/gazebo.material</uri>
            </script>
          </material>
        </visual>
        <self_collide>0</self_collide>
        <enable_wind>0</enable_wind>
        <kinematic>0</kinematic>
      </link>
      <joint name='bl_caster_wheel_joint' type='revolute'>
        <pose relative_to='bl_caster_rotation_link'>-0.0382 0 -0.094 0 -0 0</pose>
        <parent>bl_caster_rotation_link</parent>
        <child>bl_caster_wheel_link</child>
        <axis>
          <xyz>0 1 0</xyz>
          <limit>
            <lower>-1e+16</lower>
            <upper>1e+16</upper>
          </limit>
          <dynamics>
            <spring_reference>0</spring_reference>
            <spring_stiffness>0</spring_stiffness>
          </dynamics>
        </axis>
      </joint>
      <link name='bl_caster_wheel_link'>
        <pose relative_to='bl_caster_wheel_joint'>0 0 0 0 -0 0</pose>
        <inertial>
          <pose>0 0 0 1.5708 -0 0</pose>
          <mass>1</mass>
          <inertia>
            <ixx>0.0010619</ixx>
            <ixy>0</ixy>
            <ixz>0</ixz>
            <iyy>0.0010619</iyy>
            <iyz>0</iyz>
            <izz>0.00195312</izz>
          </inertia>
        </inertial>
        <collision name='bl_caster_wheel_link_collision'>
          <pose>0 0 0 1.5708 -0 0</pose>
          <geometry>
            <cylinder>
              <length>1e-05</length>
              <radius>0.0625</radius>
            </cylinder>
          </geometry>
          <surface>
            <friction>
              <ode>
                <mu>1</mu>
                <mu2>1</mu2>
                <fdir1>0 0 1</fdir1>
                <slip1>0</slip1>
                <slip2>0.5</slip2>
              </ode>
              <torsional>
                <ode/>
              </torsional>
            </friction>
            <contact>
              <ode>
                <kp>1e+08</kp>
                <min_depth>0</min_depth>
              </ode>
            </contact>
            <bounce/>
          </surface>
          <max_contacts>10</max_contacts>
        </collision>
        <visual name='bl_caster_wheel_link_visual'>
          <pose>0 0 0 0 -0 0</pose>
          <geometry>
            <mesh>
              <scale>1 1 1</scale>
              <uri>model://mir_description/meshes/visual/wheel.stl</uri>
            </mesh>
          </geometry>
          <material>
            <script>
              <name>Gazebo/DarkGrey</name>
              <uri>file://media/materials/scripts/gazebo.material</uri>
            </script>
          </material>
        </visual>
        <self_collide>0</self_collide>
        <enable_wind>0</enable_wind>
        <kinematic>0</kinematic>
      </link>
      <joint name='br_caster_rotation_joint' type='revolute'>
        <pose relative_to='base_footprint'>-0.296 -0.188 0.1565 0 -0 0</pose>
        <parent>base_footprint</parent>
        <child>br_caster_rotation_link</child>
        <axis>
          <xyz>0 0 1</xyz>
          <limit>
            <lower>-1e+16</lower>
            <upper>1e+16</upper>
          </limit>
          <dynamics>
            <damping>0</damping>
            <friction>0</friction>
            <spring_reference>0</spring_reference>
            <spring_stiffness>0</spring_stiffness>
          </dynamics>
        </axis>
      </joint>
      <link name='br_caster_rotation_link'>
        <pose relative_to='br_caster_rotation_joint'>0 0 0 0 -0 0</pose>
        <inertial>
          <pose>0 0 -0.0425 0.418879 0 1.5708</pose>
          <mass>0.309754</mass>
          <inertia>
            <ixx>0.000584452</ixx>
            <ixy>0</ixy>
            <ixz>0</ixz>
            <iyy>0.000528726</iyy>
            <iyz>0</iyz>
            <izz>0.000179236</izz>
          </inertia>
        </inertial>
        <collision name='br_caster_rotation_link_collision'>
          <pose>0 0 0 0 -0 0</pose>
          <geometry>
            <mesh>
              <scale>1 1 1</scale>
              <uri>model://mir_description/meshes/collision/caster_wheel_base.stl</uri>
            </mesh>
          </geometry>
          <surface>
            <contact>
              <ode/>
            </contact>
            <friction>
              <ode/>
              <torsional>
                <ode/>
              </torsional>
            </friction>
            <bounce/>
          </surface>
          <max_contacts>10</max_contacts>
        </collision>
        <visual name='br_caster_rotation_link_visual'>
          <pose>0 0 0 0 -0 0</pose>
          <geometry>
            <mesh>
              <scale>1 1 1</scale>
              <uri>model://mir_description/meshes/visual/caster_wheel_base.stl</uri>
            </mesh>
          </geometry>
          <material>
            <script>
              <name>Gazebo/Grey</name>
              <uri>file://media/materials/scripts/gazebo.material</uri>
            </script>
          </material>
        </visual>
        <self_collide>0</self_collide>
        <enable_wind>0</enable_wind>
        <kinematic>0</kinematic>
      </link>
      <joint name='br_caster_wheel_joint' type='revolute'>
        <pose relative_to='br_caster_rotation_link'>-0.0382 0 -0.094 0 -0 0</pose>
        <parent>br_caster_rotation_link</parent>
        <child>br_caster_wheel_link</child>
        <axis>
          <xyz>0 1 0</xyz>
          <limit>
            <lower>-1e+16</lower>
            <upper>1e+16</upper>
          </limit>
          <dynamics>
            <spring_reference>0</spring_reference>
            <spring_stiffness>0</spring_stiffness>
          </dynamics>
        </axis>
      </joint>
      <link name='br_caster_wheel_link'>
        <pose relative_to='br_caster_wheel_joint'>0 0 0 0 -0 0</pose>
        <inertial>
          <pose>0 0 0 1.5708 -0 0</pose>
          <mass>1</mass>
          <inertia>
            <ixx>0.0010619</ixx>
            <ixy>0</ixy>
            <ixz>0</ixz>
            <iyy>0.0010619</iyy>
            <iyz>0</iyz>
            <izz>0.00195312</izz>
          </inertia>
        </inertial>
        <collision name='br_caster_wheel_link_collision'>
          <pose>0 0 0 1.5708 -0 0</pose>
          <geometry>
            <cylinder>
              <length>1e-05</length>
              <radius>0.0625</radius>
            </cylinder>
          </geometry>
          <surface>
            <friction>
              <ode>
                <mu>1</mu>
                <mu2>1</mu2>
                <fdir1>0 0 1</fdir1>
                <slip1>0</slip1>
                <slip2>0.5</slip2>
              </ode>
              <torsional>
                <ode/>
              </torsional>
            </friction>
            <contact>
              <ode>
                <kp>1e+08</kp>
                <min_depth>0</min_depth>
              </ode>
            </contact>
            <bounce/>
          </surface>
          <max_contacts>10</max_contacts>
        </collision>
        <visual name='br_caster_wheel_link_visual'>
          <pose>0 0 0 0 -0 0</pose>
          <geometry>
            <mesh>
              <scale>1 1 1</scale>
              <uri>model://mir_description/meshes/visual/wheel.stl</uri>
            </mesh>
          </geometry>
          <material>
            <script>
              <name>Gazebo/DarkGrey</name>
              <uri>file://media/materials/scripts/gazebo.material</uri>
            </script>
          </material>
        </visual>
        <self_collide>0</self_collide>
        <enable_wind>0</enable_wind>
        <kinematic>0</kinematic>
      </link>
      <joint name='fl_caster_rotation_joint' type='revolute'>
        <pose relative_to='base_footprint'>0.3037 0.188 0.1565 0 -0 0</pose>
        <parent>base_footprint</parent>
        <child>fl_caster_rotation_link</child>
        <axis>
          <xyz>0 0 1</xyz>
          <limit>
            <lower>-1e+16</lower>
            <upper>1e+16</upper>
          </limit>
          <dynamics>
            <damping>0</damping>
            <friction>0</friction>
            <spring_reference>0</spring_reference>
            <spring_stiffness>0</spring_stiffness>
          </dynamics>
        </axis>
      </joint>
      <link name='fl_caster_rotation_link'>
        <pose relative_to='fl_caster_rotation_joint'>0 0 0 0 -0 0</pose>
        <inertial>
          <pose>0 0 -0.0425 0.418879 0 1.5708</pose>
          <mass>0.309754</mass>
          <inertia>
            <ixx>0.000584452</ixx>
            <ixy>0</ixy>
            <ixz>0</ixz>
            <iyy>0.000528726</iyy>
            <iyz>0</iyz>
            <izz>0.000179236</izz>
          </inertia>
        </inertial>
        <collision name='fl_caster_rotation_link_collision'>
          <pose>0 0 0 0 -0 0</pose>
          <geometry>
            <mesh>
              <scale>1 1 1</scale>
              <uri>model://mir_description/meshes/collision/caster_wheel_base.stl</uri>
            </mesh>
          </geometry>
          <surface>
            <contact>
              <ode/>
            </contact>
            <friction>
              <ode/>
              <torsional>
                <ode/>
              </torsional>
            </friction>
            <bounce/>
          </surface>
          <max_contacts>10</max_contacts>
        </collision>
        <visual name='fl_caster_rotation_link_visual'>
          <pose>0 0 0 0 -0 0</pose>
          <geometry>
            <mesh>
              <scale>1 1 1</scale>
              <uri>model://mir_description/meshes/visual/caster_wheel_base.stl</uri>
            </mesh>
          </geometry>
          <material>
            <script>
              <name>Gazebo/Grey</name>
              <uri>file://media/materials/scripts/gazebo.material</uri>
            </script>
          </material>
        </visual>
        <self_collide>0</self_collide>
        <enable_wind>0</enable_wind>
        <kinematic>0</kinematic>
      </link>
      <joint name='fl_caster_wheel_joint' type='revolute'>
        <pose relative_to='fl_caster_rotation_link'>-0.0382 0 -0.094 0 -0 0</pose>
        <parent>fl_caster_rotation_link</parent>
        <child>fl_caster_wheel_link</child>
        <axis>
          <xyz>0 1 0</xyz>
          <limit>
            <lower>-1e+16</lower>
            <upper>1e+16</upper>
          </limit>
          <dynamics>
            <spring_reference>0</spring_reference>
            <spring_stiffness>0</spring_stiffness>
          </dynamics>
        </axis>
      </joint>
      <link name='fl_caster_wheel_link'>
        <pose relative_to='fl_caster_wheel_joint'>0 0 0 0 -0 0</pose>
        <inertial>
          <pose>0 0 0 1.5708 -0 0</pose>
          <mass>1</mass>
          <inertia>
            <ixx>0.0010619</ixx>
            <ixy>0</ixy>
            <ixz>0</ixz>
            <iyy>0.0010619</iyy>
            <iyz>0</iyz>
            <izz>0.00195312</izz>
          </inertia>
        </inertial>
        <collision name='fl_caster_wheel_link_collision'>
          <pose>0 0 0 1.5708 -0 0</pose>
          <geometry>
            <cylinder>
              <length>1e-05</length>
              <radius>0.0625</radius>
            </cylinder>
          </geometry>
          <surface>
            <friction>
              <ode>
                <mu>1</mu>
                <mu2>1</mu2>
                <fdir1>0 0 1</fdir1>
                <slip1>0</slip1>
                <slip2>0.5</slip2>
              </ode>
              <torsional>
                <ode/>
              </torsional>
            </friction>
            <contact>
              <ode>
                <kp>1e+08</kp>
                <min_depth>0</min_depth>
              </ode>
            </contact>
            <bounce/>
          </surface>
          <max_contacts>10</max_contacts>
        </collision>
        <visual name='fl_caster_wheel_link_visual'>
          <pose>0 0 0 0 -0 0</pose>
          <geometry>
            <mesh>
              <scale>1 1 1</scale>
              <uri>model://mir_description/meshes/visual/wheel.stl</uri>
            </mesh>
          </geometry>
          <material>
            <script>
              <name>Gazebo/DarkGrey</name>
              <uri>file://media/materials/scripts/gazebo.material</uri>
            </script>
          </material>
        </visual>
        <self_collide>0</self_collide>
        <enable_wind>0</enable_wind>
        <kinematic>0</kinematic>
      </link>
      <joint name='fr_caster_rotation_joint' type='revolute'>
        <pose relative_to='base_footprint'>0.3037 -0.188 0.1565 0 -0 0</pose>
        <parent>base_footprint</parent>
        <child>fr_caster_rotation_link</child>
        <axis>
          <xyz>0 0 1</xyz>
          <limit>
            <lower>-1e+16</lower>
            <upper>1e+16</upper>
          </limit>
          <dynamics>
            <damping>0</damping>
            <friction>0</friction>
            <spring_reference>0</spring_reference>
            <spring_stiffness>0</spring_stiffness>
          </dynamics>
        </axis>
      </joint>
      <link name='fr_caster_rotation_link'>
        <pose relative_to='fr_caster_rotation_joint'>0 0 0 0 -0 0</pose>
        <inertial>
          <pose>0 0 -0.0425 0.418879 0 1.5708</pose>
          <mass>0.309754</mass>
          <inertia>
            <ixx>0.000584452</ixx>
            <ixy>0</ixy>
            <ixz>0</ixz>
            <iyy>0.000528726</iyy>
            <iyz>0</iyz>
            <izz>0.000179236</izz>
          </inertia>
        </inertial>
        <collision name='fr_caster_rotation_link_collision'>
          <pose>0 0 0 0 -0 0</pose>
          <geometry>
            <mesh>
              <scale>1 1 1</scale>
              <uri>model://mir_description/meshes/collision/caster_wheel_base.stl</uri>
            </mesh>
          </geometry>
          <surface>
            <contact>
              <ode/>
            </contact>
            <friction>
              <ode/>
              <torsional>
                <ode/>
              </torsional>
            </friction>
            <bounce/>
          </surface>
          <max_contacts>10</max_contacts>
        </collision>
        <visual name='fr_caster_rotation_link_visual'>
          <pose>0 0 0 0 -0 0</pose>
          <geometry>
            <mesh>
              <scale>1 1 1</scale>
              <uri>model://mir_description/meshes/visual/caster_wheel_base.stl</uri>
            </mesh>
          </geometry>
          <material>
            <script>
              <name>Gazebo/Grey</name>
              <uri>file://media/materials/scripts/gazebo.material</uri>
            </script>
          </material>
        </visual>
        <self_collide>0</self_collide>
        <enable_wind>0</enable_wind>
        <kinematic>0</kinematic>
      </link>
      <joint name='fr_caster_wheel_joint' type='revolute'>
        <pose relative_to='fr_caster_rotation_link'>-0.0382 0 -0.094 0 -0 0</pose>
        <parent>fr_caster_rotation_link</parent>
        <child>fr_caster_wheel_link</child>
        <axis>
          <xyz>0 1 0</xyz>
          <limit>
            <lower>-1e+16</lower>
            <upper>1e+16</upper>
          </limit>
          <dynamics>
            <spring_reference>0</spring_reference>
            <spring_stiffness>0</spring_stiffness>
          </dynamics>
        </axis>
      </joint>
      <link name='fr_caster_wheel_link'>
        <pose relative_to='fr_caster_wheel_joint'>0 0 0 0 -0 0</pose>
        <inertial>
          <pose>0 0 0 1.5708 -0 0</pose>
          <mass>1</mass>
          <inertia>
            <ixx>0.0010619</ixx>
            <ixy>0</ixy>
            <ixz>0</ixz>
            <iyy>0.0010619</iyy>
            <iyz>0</iyz>
            <izz>0.00195312</izz>
          </inertia>
        </inertial>
        <collision name='fr_caster_wheel_link_collision'>
          <pose>0 0 0 1.5708 -0 0</pose>
          <geometry>
            <cylinder>
              <length>1e-05</length>
              <radius>0.0625</radius>
            </cylinder>
          </geometry>
          <surface>
            <friction>
              <ode>
                <mu>1</mu>
                <mu2>1</mu2>
                <fdir1>0 0 1</fdir1>
                <slip1>0</slip1>
                <slip2>0.5</slip2>
              </ode>
              <torsional>
                <ode/>
              </torsional>
            </friction>
            <contact>
              <ode>
                <kp>1e+08</kp>
                <min_depth>0</min_depth>
              </ode>
            </contact>
            <bounce/>
          </surface>
          <max_contacts>10</max_contacts>
        </collision>
        <visual name='fr_caster_wheel_link_visual'>
          <pose>0 0 0 0 -0 0</pose>
          <geometry>
            <mesh>
              <scale>1 1 1</scale>
              <uri>model://mir_description/meshes/visual/wheel.stl</uri>
            </mesh>
          </geometry>
          <material>
            <script>
              <name>Gazebo/DarkGrey</name>
              <uri>file://media/materials/scripts/gazebo.material</uri>
            </script>
          </material>
        </visual>
        <self_collide>0</self_collide>
        <enable_wind>0</enable_wind>
        <kinematic>0</kinematic>
      </link>
      <joint name='left_wheel_joint' type='revolute'>
        <pose relative_to='base_footprint'>0 0.2015 0.1 0 -0 0</pose>
        <parent>base_footprint</parent>
        <child>left_wheel_link</child>
        <axis>
          <xyz>0 1 0</xyz>
          <limit>
            <effort>250</effort>
            <velocity>20</velocity>
            <lower>-1e+16</lower>
            <upper>1e+16</upper>
          </limit>
          <dynamics>
            <spring_reference>0</spring_reference>
            <spring_stiffness>0</spring_stiffness>
          </dynamics>
        </axis>
      </joint>
      <link name='left_wheel_link'>
        <pose relative_to='left_wheel_joint'>0 0 0 0 -0 0</pose>
        <inertial>
          <pose>0 0 0 1.5708 -0 0</pose>
          <mass>1</mass>
          <inertia>
            <ixx>0.00262033</ixx>
            <ixy>0</ixy>
            <ixz>0</ixz>
            <iyy>0.00262033</iyy>
            <iyz>0</iyz>
            <izz>0.005</izz>
          </inertia>
        </inertial>
        <collision name='left_wheel_link_collision'>
          <pose>0 0 0 1.5708 -0 0</pose>
          <geometry>
            <cylinder>
              <length>0.038</length>
              <radius>0.1</radius>
            </cylinder>
          </geometry>
          <surface>
            <friction>
              <ode>
                <mu>300</mu>
                <mu2>300</mu2>
                <fdir1>0 0 1</fdir1>
              </ode>
              <torsional>
                <coefficient>300</coefficient>
                <use_patch_radius>0</use_patch_radius>
                <surface_radius>0.1</surface_radius>
                <ode/>
              </torsional>
            </friction>
            <contact>
              <ode>
                <min_depth>0.001</min_depth>
              </ode>
            </contact>
            <bounce/>
          </surface>
          <max_contacts>10</max_contacts>
        </collision>
        <visual name='left_wheel_link_visual'>
          <pose>0 0 0 1.5708 -0 0</pose>
          <geometry>
            <cylinder>
              <length>0.038</length>
              <radius>0.1</radius>
            </cylinder>
          </geometry>
          <material>
            <script>
              <name>Gazebo/DarkGrey</name>
              <uri>file://media/materials/scripts/gazebo.material</uri>
            </script>
          </material>
        </visual>
        <self_collide>0</self_collide>
        <enable_wind>0</enable_wind>
        <kinematic>0</kinematic>
      </link>
      <joint name='right_wheel_joint' type='revolute'>
        <pose relative_to='base_footprint'>0 -0.2015 0.1 0 -0 0</pose>
        <parent>base_footprint</parent>
        <child>right_wheel_link</child>
        <axis>
          <xyz>0 1 0</xyz>
          <limit>
            <effort>250</effort>
            <velocity>20</velocity>
            <lower>-1e+16</lower>
            <upper>1e+16</upper>
          </limit>
          <dynamics>
            <spring_reference>0</spring_reference>
            <spring_stiffness>0</spring_stiffness>
          </dynamics>
        </axis>
      </joint>
      <link name='right_wheel_link'>
        <pose relative_to='right_wheel_joint'>0 0 0 0 -0 0</pose>
        <inertial>
          <pose>0 0 0 1.5708 -0 0</pose>
          <mass>1</mass>
          <inertia>
            <ixx>0.00262033</ixx>
            <ixy>0</ixy>
            <ixz>0</ixz>
            <iyy>0.00262033</iyy>
            <iyz>0</iyz>
            <izz>0.005</izz>
          </inertia>
        </inertial>
        <collision name='right_wheel_link_collision'>
          <pose>0 0 0 1.5708 -0 0</pose>
          <geometry>
            <cylinder>
              <length>0.038</length>
              <radius>0.1</radius>
            </cylinder>
          </geometry>
          <surface>
            <friction>
              <ode>
                <mu>300</mu>
                <mu2>300</mu2>
                <fdir1>0 0 1</fdir1>
              </ode>
              <torsional>
                <coefficient>300</coefficient>
                <use_patch_radius>0</use_patch_radius>
                <surface_radius>0.1</surface_radius>
                <ode/>
              </torsional>
            </friction>
            <contact>
              <ode>
                <min_depth>0.001</min_depth>
              </ode>
            </contact>
            <bounce/>
          </surface>
          <max_contacts>10</max_contacts>
        </collision>
        <visual name='right_wheel_link_visual'>
          <pose>0 0 0 1.5708 -0 0</pose>
          <geometry>
            <cylinder>
              <length>0.038</length>
              <radius>0.1</radius>
            </cylinder>
          </geometry>
          <material>
            <script>
              <name>Gazebo/DarkGrey</name>
              <uri>file://media/materials/scripts/gazebo.material</uri>
            </script>
          </material>
        </visual>
        <self_collide>0</self_collide>
        <enable_wind>0</enable_wind>
        <kinematic>0</kinematic>
      </link>
      <joint name='ur_shoulder_pan_joint' type='revolute'>
        <pose relative_to='base_footprint'>0.135 0 0.9525 0 -0 1.5708</pose>
        <parent>base_footprint</parent>
        <child>ur_shoulder_link</child>
        <axis>
          <xyz>0 0 1</xyz>
          <limit>
            <lower>-6.28319</lower>
            <upper>6.28319</upper>
            <effort>150</effort>
            <velocity>3.14159</velocity>
          </limit>
          <dynamics>
            <damping>0</damping>
            <friction>0</friction>
            <spring_reference>0</spring_reference>
            <spring_stiffness>0</spring_stiffness>
          </dynamics>
        </axis>
      </joint>
      <link name='ur_shoulder_link'>
        <pose relative_to='ur_shoulder_pan_joint'>0 0 0 0 -0 0</pose>
        <inertial>
          <pose>0 -0.00193 -0.02561 1.5708 -0 0</pose>
          <mass>0.2</mass>
          <inertia>
            <ixx>0.0070021</ixx>
            <ixy>7.3e-07</ixy>
            <ixz>-1.053e-05</ixz>
            <iyy>0.00648091</iyy>
            <iyz>0.00049994</iyz>
            <izz>0.00657286</izz>
          </inertia>
        </inertial>
        <collision name='ur_shoulder_link_collision'>
          <pose>0 0 0 0 -0 3.14159</pose>
          <geometry>
            <mesh>
              <scale>1 1 1</scale>
              <uri>file:///home/dikki/ros2_ws_simulation/install/ur_description/share/ur_description/meshes/ur5e/collision/shoulder.stl</uri>
            </mesh>
          </geometry>
          <max_contacts>10</max_contacts>
          <surface>
            <contact>
              <ode/>
            </contact>
            <bounce/>
            <friction>
              <torsional>
                <ode/>
              </torsional>
              <ode/>
            </friction>
          </surface>
        </collision>
        <visual name='ur_shoulder_link_visual'>
          <pose>0 0 0 0 -0 3.14159</pose>
          <geometry>
            <mesh>
              <scale>1 1 1</scale>
              <uri>file:///home/dikki/ros2_ws_simulation/install/ur_description/share/ur_description/meshes/ur5e/visual/shoulder.dae</uri>
            </mesh>
          </geometry>
        </visual>
        <self_collide>0</self_collide>
        <enable_wind>0</enable_wind>
        <kinematic>0</kinematic>
      </link>
      <joint name='ur_shoulder_lift_joint' type='revolute'>
        <pose relative_to='ur_shoulder_link'>0 0 0 1.5708 -0 0</pose>
        <parent>ur_shoulder_link</parent>
        <child>ur_upper_arm_link</child>
        <axis>
          <xyz>0 0 1</xyz>
          <limit>
            <lower>-6.28319</lower>
            <upper>6.28319</upper>
            <effort>150</effort>
            <velocity>3.14159</velocity>
          </limit>
          <dynamics>
            <damping>0</damping>
            <friction>0</friction>
            <spring_reference>0</spring_reference>
            <spring_stiffness>0</spring_stiffness>
          </dynamics>
        </axis>
      </joint>
      <link name='ur_upper_arm_link'>
        <pose relative_to='ur_shoulder_lift_joint'>0 0 0 0 -0 0</pose>
        <inertial>
          <pose>-0.2125 0 0.11336 0 -0 0</pose>
          <mass>0.2</mass>
          <inertia>
            <ixx>0.0150589</ixx>
            <ixy>-5.4e-05</ixy>
            <ixz>5.63e-06</ixz>
            <iyy>0.333881</iyy>
            <iyz>-1.81e-06</iyz>
            <izz>0.332472</izz>
          </inertia>
        </inertial>
        <collision name='ur_upper_arm_link_collision'>
          <pose>0 0 0.138 1.5708 0 -1.5708</pose>
          <geometry>
            <mesh>
              <scale>1 1 1</scale>
              <uri>file:///home/dikki/ros2_ws_simulation/install/ur_description/share/ur_description/meshes/ur5e/collision/upperarm.stl</uri>
            </mesh>
          </geometry>
          <max_contacts>10</max_contacts>
          <surface>
            <contact>
              <ode/>
            </contact>
            <bounce/>
            <friction>
              <torsional>
                <ode/>
              </torsional>
              <ode/>
            </friction>
          </surface>
        </collision>
        <visual name='ur_upper_arm_link_visual'>
          <pose>0 0 0.138 1.5708 0 -1.5708</pose>
          <geometry>
            <mesh>
              <scale>1 1 1</scale>
              <uri>file:///home/dikki/ros2_ws_simulation/install/ur_description/share/ur_description/meshes/ur5e/visual/upperarm.dae</uri>
            </mesh>
          </geometry>
        </visual>
        <self_collide>0</self_collide>
        <enable_wind>0</enable_wind>
        <kinematic>0</kinematic>
      </link>
      <joint name='ur_elbow_joint' type='revolute'>
        <pose relative_to='ur_upper_arm_link'>-0.425 0 0 0 -0 0</pose>
        <parent>ur_upper_arm_link</parent>
        <child>ur_forearm_link</child>
        <axis>
          <xyz>0 0 1</xyz>
          <limit>
            <lower>-3.14159</lower>
            <upper>3.14159</upper>
            <effort>150</effort>
            <velocity>3.14159</velocity>
          </limit>
          <dynamics>
            <damping>0</damping>
            <friction>0</friction>
            <spring_reference>0</spring_reference>
            <spring_stiffness>0</spring_stiffness>
          </dynamics>
        </axis>
      </joint>
      <link name='ur_forearm_link'>
        <pose relative_to='ur_elbow_joint'>0 0 0 0 -0 0</pose>
        <inertial>
          <pose>-0.2422 0 0.0265 0 -0 0</pose>
          <mass>0.2</mass>
          <inertia>
            <ixx>0.00399632</ixx>
            <ixy>-1.365e-05</ixy>
            <ixz>0.00137272</ixz>
            <iyy>0.0787925</iyy>
            <iyz>-6.6e-06</iyz>
            <izz>0.0784851</izz>
          </inertia>
        </inertial>
        <collision name='ur_forearm_link_collision'>
          <pose>0 0 0.007 1.5708 0 -1.5708</pose>
          <geometry>
            <mesh>
              <scale>1 1 1</scale>
              <uri>file:///home/dikki/ros2_ws_simulation/install/ur_description/share/ur_description/meshes/ur5e/collision/forearm.stl</uri>
            </mesh>
          </geometry>
          <max_contacts>10</max_contacts>
          <surface>
            <contact>
              <ode/>
            </contact>
            <bounce/>
            <friction>
              <torsional>
                <ode/>
              </torsional>
              <ode/>
            </friction>
          </surface>
        </collision>
        <visual name='ur_forearm_link_visual'>
          <pose>0 0 0.007 1.5708 0 -1.5708</pose>
          <geometry>
            <mesh>
              <scale>1 1 1</scale>
              <uri>file:///home/dikki/ros2_ws_simulation/install/ur_description/share/ur_description/meshes/ur5e/visual/forearm.dae</uri>
            </mesh>
          </geometry>
        </visual>
        <self_collide>0</self_collide>
        <enable_wind>0</enable_wind>
        <kinematic>0</kinematic>
      </link>
      <joint name='ur_wrist_1_joint' type='revolute'>
        <pose relative_to='ur_forearm_link'>-0.3922 0 0.1333 0 -0 0</pose>
        <parent>ur_forearm_link</parent>
        <child>ur_wrist_1_link</child>
        <axis>
          <xyz>0 0 1</xyz>
          <limit>
            <lower>-6.28319</lower>
            <upper>6.28319</upper>
            <effort>28</effort>
            <velocity>3.14159</velocity>
          </limit>
          <dynamics>
            <damping>0</damping>
            <friction>0</friction>
            <spring_reference>0</spring_reference>
            <spring_stiffness>0</spring_stiffness>
          </dynamics>
        </axis>
      </joint>
      <link name='ur_wrist_1_link'>
        <pose relative_to='ur_wrist_1_joint'>0 0 0 0 -0 0</pose>
        <inertial>
          <pose>0 -0.01634 -0.0018 1.5708 -0 0</pose>
          <mass>0.2</mass>
          <inertia>
            <ixx>0.00165491</ixx>
            <ixy>-2.82e-06</ixy>
            <ixz>-4.38e-06</ixz>
            <iyy>0.00135962</iyy>
            <iyz>0.00010157</iyz>
            <izz>0.00126279</izz>
          </inertia>
        </inertial>
        <collision name='ur_wrist_1_link_collision'>
          <pose>0 0 -0.127 1.5708 -0 0</pose>
          <geometry>
            <mesh>
              <scale>1 1 1</scale>
              <uri>file:///home/dikki/ros2_ws_simulation/install/ur_description/share/ur_description/meshes/ur5e/collision/wrist1.stl</uri>
            </mesh>
          </geometry>
          <max_contacts>10</max_contacts>
          <surface>
            <contact>
              <ode/>
            </contact>
            <bounce/>
            <friction>
              <torsional>
                <ode/>
              </torsional>
              <ode/>
            </friction>
          </surface>
        </collision>
        <visual name='ur_wrist_1_link_visual'>
          <pose>0 0 -0.127 1.5708 -0 0</pose>
          <geometry>
            <mesh>
              <scale>1 1 1</scale>
              <uri>file:///home/dikki/ros2_ws_simulation/install/ur_description/share/ur_description/meshes/ur5e/visual/wrist1.dae</uri>
            </mesh>
          </geometry>
        </visual>
        <self_collide>0</self_collide>
        <enable_wind>0</enable_wind>
        <kinematic>0</kinematic>
      </link>
      <joint name='ur_wrist_2_joint' type='revolute'>
        <pose relative_to='ur_wrist_1_link'>0 -0.0997 -0 1.5708 -0 0</pose>
        <parent>ur_wrist_1_link</parent>
        <child>ur_wrist_2_link</child>
        <axis>
          <xyz>0 0 1</xyz>
          <limit>
            <lower>-6.28319</lower>
            <upper>6.28319</upper>
            <effort>28</effort>
            <velocity>3.14159</velocity>
          </limit>
          <dynamics>
            <damping>0</damping>
            <friction>0</friction>
            <spring_reference>0</spring_reference>
            <spring_stiffness>0</spring_stiffness>
          </dynamics>
        </axis>
      </joint>
      <link name='ur_wrist_2_link'>
        <pose relative_to='ur_wrist_2_joint'>0 0 0 0 -0 0</pose>
        <inertial>
          <pose>0 0.01634 -0.0018 -1.5708 0 0</pose>
          <mass>0.2</mass>
          <inertia>
            <ixx>0.00135617</ixx>
            <ixy>-2.74e-06</ixy>
            <ixz>4.44e-06</ixz>
            <iyy>0.00127827</iyy>
            <iyz>-5.048e-05</iyz>
            <izz>0.00096614</izz>
          </inertia>
        </inertial>
        <collision name='ur_wrist_2_link_collision'>
          <pose>0 0 -0.0997 0 -0 0</pose>
          <geometry>
            <mesh>
              <scale>1 1 1</scale>
              <uri>file:///home/dikki/ros2_ws_simulation/install/ur_description/share/ur_description/meshes/ur5e/collision/wrist2.stl</uri>
            </mesh>
          </geometry>
          <max_contacts>10</max_contacts>
          <surface>
            <contact>
              <ode/>
            </contact>
            <bounce/>
            <friction>
              <torsional>
                <ode/>
              </torsional>
              <ode/>
            </friction>
          </surface>
        </collision>
        <visual name='ur_wrist_2_link_visual'>
          <pose>0 0 -0.0997 0 -0 0</pose>
          <geometry>
            <mesh>
              <scale>1 1 1</scale>
              <uri>file:///home/dikki/ros2_ws_simulation/install/ur_description/share/ur_description/meshes/ur5e/visual/wrist2.dae</uri>
            </mesh>
          </geometry>
        </visual>
        <self_collide>0</self_collide>
        <enable_wind>0</enable_wind>
        <kinematic>0</kinematic>
      </link>
      <joint name='ur_wrist_3_joint' type='revolute'>
        <pose relative_to='ur_wrist_2_link'>0 0.0996 -0 -1.5708 0 0</pose>
        <parent>ur_wrist_2_link</parent>
        <child>ur_wrist_3_link</child>
        <axis>
          <xyz>0 0 1</xyz>
          <limit>
            <lower>-6.28319</lower>
            <upper>6.28319</upper>
            <effort>28</effort>
            <velocity>3.14159</velocity>
          </limit>
          <dynamics>
            <damping>0</damping>
            <friction>0</friction>
            <spring_reference>0</spring_reference>
            <spring_stiffness>0</spring_stiffness>
          </dynamics>
        </axis>
      </joint>
      <link name='ur_wrist_3_link'>
        <pose relative_to='ur_wrist_3_joint'>0 0 0 0 -0 0</pose>
        <inertial>
          <pose>-0.003418 -0.012019 0.004059 0 -0 0</pose>
          <mass>0.44</mass>
          <inertia>
            <ixx>0.00115043</ixx>
            <ixy>-7.44721e-05</ixy>
            <ixz>3.14708e-05</ixz>
            <iyy>0.000337836</iyy>
            <iyz>0.000139528</iyz>
            <izz>0.000745922</izz>
          </inertia>
        </inertial>
        <collision name='ur_wrist_3_link_collision'>
          <pose>0 0 -0.0989 1.5708 -0 0</pose>
          <geometry>
            <mesh>
              <scale>1 1 1</scale>
              <uri>file:///home/dikki/ros2_ws_simulation/install/ur_description/share/ur_description/meshes/ur5e/collision/wrist3.stl</uri>
            </mesh>
          </geometry>
          <max_contacts>10</max_contacts>
          <surface>
            <contact>
              <ode/>
            </contact>
            <bounce/>
            <friction>
              <torsional>
                <ode/>
              </torsional>
              <ode/>
            </friction>
          </surface>
        </collision>
        <collision name='ur_wrist_3_link_fixed_joint_lump__camera_mount_collision_1'>
          <pose>0.05 0.03 0.035 -1.5708 -0 -3.14159</pose>
          <geometry>
            <mesh>
              <scale>0.001 0.001 0.001</scale>
              <uri>model://mir_description/meshes/collision/D435i_mounted.STL</uri>
            </mesh>
          </geometry>
          <max_contacts>10</max_contacts>
          <surface>
            <contact>
              <ode/>
            </contact>
            <bounce/>
            <friction>
              <torsional>
                <ode/>
              </torsional>
              <ode/>
            </friction>
          </surface>
        </collision>
        <collision name='ur_wrist_3_link_fixed_joint_lump__realsense_link_collision_2'>
          <pose>0 -0.0735 0.0306 -1.57079 -1.57079 3.14159</pose>
          <geometry>
            <box>
              <size>0.02505 0.09 0.025</size>
            </box>
          </geometry>
          <surface>
            <contact>
              <ode>
                <kp>1e+13</kp>
                <kd>1</kd>
              </ode>
            </contact>
            <friction>
              <ode>
                <mu2>1</mu2>
                <fdir1>0 0 0</fdir1>
              </ode>
              <torsional>
                <ode/>
              </torsional>
            </friction>
            <bounce/>
          </surface>
          <max_contacts>10</max_contacts>
        </collision>
        <collision name='ur_wrist_3_link_fixed_joint_lump__gripper_soft_robotics_gripper_base_link_collision_3'>
          <pose>0 0 -0.0095 0 -0 1.5708</pose>
          <geometry>
            <mesh>
              <scale>1 1 1</scale>
              <uri>file:///home/dikki/ros2_ws_simulation/install/gripper_description/share/gripper_description/models/meshes/base.stl</uri>
            </mesh>
          </geometry>
          <surface>
            <contact>
              <ode/>
            </contact>
            <friction>
              <ode/>
              <torsional>
                <ode/>
              </torsional>
            </friction>
            <bounce/>
          </surface>
          <max_contacts>10</max_contacts>
        </collision>
        <visual name='ur_wrist_3_link_visual'>
          <pose>0 0 -0.0989 1.5708 -0 0</pose>
          <geometry>
            <mesh>
              <scale>1 1 1</scale>
              <uri>file:///home/dikki/ros2_ws_simulation/install/ur_description/share/ur_description/meshes/ur5e/visual/wrist3.dae</uri>
            </mesh>
          </geometry>
        </visual>
        <visual name='ur_wrist_3_link_fixed_joint_lump__camera_mount_visual_1'>
          <pose>0.05 0.03 0.035 -1.5708 -0 -3.14159</pose>
          <geometry>
            <mesh>
              <scale>0.001 0.001 0.001</scale>
              <uri>model://mir_description/meshes/visual/D435i_mounted.STL</uri>
            </mesh>
          </geometry>
        </visual>
        <visual name='ur_wrist_3_link_fixed_joint_lump__realsense_link_visual_2'>
          <pose>0 -0.0735 0.0349 -0 -0 -3.14159</pose>
          <geometry>
            <mesh>
              <scale>1 1 1</scale>
              <uri>file:///home/dikki/ros2_ws_simulation/install/realsense2_description/share/realsense2_description/meshes/d435.dae</uri>
            </mesh>
          </geometry>
        </visual>
        <visual name='ur_wrist_3_link_fixed_joint_lump__gripper_soft_robotics_gripper_base_link_visual_3'>
          <pose>0 0 -0.0095 0 -0 1.5708</pose>
          <geometry>
            <mesh>
              <scale>1 1 1</scale>
              <uri>file:///home/dikki/ros2_ws_simulation/install/gripper_description/share/gripper_description/models/meshes/base.stl</uri>
            </mesh>
          </geometry>
          <material>
            <script>
              <name>Gazebo/Grey</name>
              <uri>file://media/materials/scripts/gazebo.material</uri>
            </script>
          </material>
        </visual>
        <self_collide>0</self_collide>
        <enable_wind>0</enable_wind>
        <kinematic>0</kinematic>
        <sensor name='realsensecolor' type='camera'>
          <camera name='realsense'>
            <horizontal_fov>1.21126</horizontal_fov>
            <image>
              <width>1920</width>
              <height>1080</height>
              <format>RGB_INT8</format>
            </image>
            <clip>
              <near>0.1</near>
              <far>100</far>
            </clip>
            <noise>
              <type>gaussian</type>
              <mean>0</mean>
              <stddev>0.007</stddev>
            </noise>
          </camera>
          <always_on>1</always_on>
          <update_rate>30</update_rate>
          <visualize>1</visualize>
          <pose>-0.0175 -0.0735 0.0306 -3.14159 -1.57079 -1.57079</pose>
        </sensor>
        <sensor name='realsenseired1' type='camera'>
          <camera name='realsense'>
            <horizontal_fov>1.48702</horizontal_fov>
            <image>
              <width>848</width>
              <height>480</height>
              <format>L_INT8</format>
            </image>
            <clip>
              <near>0.1</near>
              <far>100</far>
            </clip>
            <noise>
              <type>gaussian</type>
              <mean>0</mean>
              <stddev>0.05</stddev>
            </noise>
          </camera>
          <always_on>1</always_on>
          <update_rate>60</update_rate>
          <visualize>0</visualize>
          <pose>-0.0175 -0.0735 0.0306 -3.14159 -1.57079 -1.57079</pose>
        </sensor>
        <sensor name='realsenseired2' type='camera'>
          <camera name='realsense'>
            <horizontal_fov>1.48702</horizontal_fov>
            <image>
              <width>848</width>
              <height>480</height>
              <format>L_INT8</format>
            </image>
            <clip>
              <near>0.1</near>
              <far>100</far>
            </clip>
            <noise>
              <type>gaussian</type>
              <mean>0</mean>
              <stddev>0.05</stddev>
            </noise>
          </camera>
          <always_on>1</always_on>
          <update_rate>60</update_rate>
          <visualize>0</visualize>
          <pose>-0.0175 -0.0735 0.0306 -3.14159 -1.57079 -1.57079</pose>
        </sensor>
        <sensor name='realsensedepth' type='depth'>
          <camera name='realsense'>
            <horizontal_fov>1.48702</horizontal_fov>
            <image>
              <width>848</width>
              <height>480</height>
            </image>
            <clip>
              <near>0.1</near>
              <far>100</far>
            </clip>
            <noise>
              <type>gaussian</type>
              <mean>0</mean>
              <stddev>0.1</stddev>
            </noise>
          </camera>
          <always_on>1</always_on>
          <update_rate>60</update_rate>
          <visualize>0</visualize>
          <pose>-0.0175 -0.0735 0.0306 -3.14159 -1.57079 -1.57079</pose>
        </sensor>
        <sensor name='realsenseimu' type='imu'>
          <always_on>1</always_on>
          <update_rate>200</update_rate>
          <topic>__default_topic__</topic>
          <plugin name='realsenseimu' filename='libgazebo_ros_imu_sensor.so'>
            <ros>
              <namespace>/camera</namespace>
              <remapping>~/out:=imu</remapping>
            </ros>
            <bodyName>realsense_link</bodyName>
            <frameName>realsense_gyro_optical_frame</frameName>
            <updateRateHZ>200</updateRateHZ>
            <gaussianNoise>0.1</gaussianNoise>
            <xyzOffset>0 0 0</xyzOffset>
            <rpyOffset>0 0 0</rpyOffset>
          </plugin>
          <pose>-0.0175 -0.0735 0.0306 -3.14159 -1.57079 -1.57079</pose>
          <imu/>
        </sensor>
      </link>
      <joint name='gripper_soft_robotics_gripper_left_finger_joint1' type='revolute'>
        <pose relative_to='ur_wrist_3_link'>0.028 0 0.09 0 -0 1.5708</pose>
        <parent>ur_wrist_3_link</parent>
        <child>gripper_soft_robotics_left_finger_link1</child>
        <axis>
          <xyz>1 0 0</xyz>
          <limit>
            <lower>-0.35</lower>
            <upper>0.35</upper>
            <effort>1</effort>
            <velocity>1</velocity>
          </limit>
          <dynamics>
            <spring_reference>0</spring_reference>
            <spring_stiffness>0</spring_stiffness>
          </dynamics>
        </axis>
      </joint>
      <link name='gripper_soft_robotics_left_finger_link1'>
        <pose relative_to='gripper_soft_robotics_gripper_left_finger_joint1'>0 0 0 0 -0 0</pose>
        <inertial>
          <pose>2.1e-05 0.005953 0.019895 0 -0 0</pose>
          <mass>0.336</mass>
          <inertia>
            <ixx>0.000288919</ixx>
            <ixy>1.04302e-08</ixy>
            <ixz>-5.48766e-08</ixz>
            <iyy>0.000305194</iyy>
            <iyz>-3.06698e-05</iyz>
            <izz>0.000290443</izz>
          </inertia>
        </inertial>
        <collision name='gripper_soft_robotics_left_finger_link1_collision'>
          <pose>0 0 0 0 -0 0</pose>
          <geometry>
            <mesh>
              <scale>1 1 1</scale>
              <uri>file:///home/dikki/ros2_ws_simulation/install/gripper_description/share/gripper_description/models/meshes/link1.stl</uri>
            </mesh>
          </geometry>
          <surface>
            <contact>
              <ode/>
            </contact>
            <friction>
              <ode/>
              <torsional>
                <ode/>
              </torsional>
            </friction>
            <bounce/>
          </surface>
          <max_contacts>10</max_contacts>
        </collision>
        <collision name='gripper_soft_robotics_left_finger_link1_fixed_joint_lump__gripper_soft_robotics_left_finger_link2_collision_1'>
          <pose>0 0.009 0.042 0 -0 0</pose>
          <geometry>
            <mesh>
              <scale>1 1 1</scale>
              <uri>file:///home/dikki/ros2_ws_simulation/install/gripper_description/share/gripper_description/models/meshes/link2.stl</uri>
            </mesh>
          </geometry>
          <surface>
            <contact>
              <ode/>
            </contact>
            <friction>
              <ode/>
              <torsional>
                <ode/>
              </torsional>
            </friction>
            <bounce/>
          </surface>
          <max_contacts>10</max_contacts>
        </collision>
        <visual name='gripper_soft_robotics_left_finger_link1_visual'>
          <pose>0 0 0 0 -0 0</pose>
          <geometry>
            <mesh>
              <scale>1 1 1</scale>
              <uri>file:///home/dikki/ros2_ws_simulation/install/gripper_description/share/gripper_description/models/meshes/link1.stl</uri>
            </mesh>
          </geometry>
          <material>
            <script>
              <name>Gazebo/Blue</name>
              <uri>file://media/materials/scripts/gazebo.material</uri>
            </script>
          </material>
        </visual>
        <visual name='gripper_soft_robotics_left_finger_link1_fixed_joint_lump__gripper_soft_robotics_left_finger_link2_visual_1'>
          <pose>0 0.009 0.042 0 -0 0</pose>
          <geometry>
            <mesh>
              <scale>1 1 1</scale>
              <uri>file:///home/dikki/ros2_ws_simulation/install/gripper_description/share/gripper_description/models/meshes/link2.stl</uri>
            </mesh>
          </geometry>
          <material>
            <script>
              <name>Gazebo/Blue</name>
              <uri>file://media/materials/scripts/gazebo.material</uri>
            </script>
          </material>
        </visual>
        <self_collide>0</self_collide>
        <enable_wind>0</enable_wind>
        <kinematic>0</kinematic>
      </link>
      <joint name='gripper_soft_robotics_gripper_right_finger_joint1' type='revolute'>
        <pose relative_to='ur_wrist_3_link'>-0.028 0 0.09 0 -0 -1.5708</pose>
        <parent>ur_wrist_3_link</parent>
        <child>gripper_soft_robotics_right_finger_link1</child>
        <axis>
          <xyz>1 0 0</xyz>
          <limit>
            <lower>-0.35</lower>
            <upper>0.35</upper>
            <effort>1</effort>
            <velocity>1</velocity>
          </limit>
          <dynamics>
            <spring_reference>0</spring_reference>
            <spring_stiffness>0</spring_stiffness>
          </dynamics>
        </axis>
      </joint>
      <link name='gripper_soft_robotics_right_finger_link1'>
        <pose relative_to='gripper_soft_robotics_gripper_right_finger_joint1'>0 0 0 0 -0 0</pose>
        <inertial>
          <pose>2.1e-05 0.005953 0.019895 0 -0 0</pose>
          <mass>0.336</mass>
          <inertia>
            <ixx>0.000288919</ixx>
            <ixy>1.04302e-08</ixy>
            <ixz>-5.48766e-08</ixz>
            <iyy>0.000305194</iyy>
            <iyz>-3.06698e-05</iyz>
            <izz>0.000290443</izz>
          </inertia>
        </inertial>
        <collision name='gripper_soft_robotics_right_finger_link1_collision'>
          <pose>0 0 0 0 -0 0</pose>
          <geometry>
            <mesh>
              <scale>1 1 1</scale>
              <uri>file:///home/dikki/ros2_ws_simulation/install/gripper_description/share/gripper_description/models/meshes/link1.stl</uri>
            </mesh>
          </geometry>
          <surface>
            <contact>
              <ode/>
            </contact>
            <friction>
              <ode/>
              <torsional>
                <ode/>
              </torsional>
            </friction>
            <bounce/>
          </surface>
          <max_contacts>10</max_contacts>
        </collision>
        <collision name='gripper_soft_robotics_right_finger_link1_fixed_joint_lump__gripper_soft_robotics_right_finger_link2_collision_1'>
          <pose>0 0.009 0.042 0 -0 0</pose>
          <geometry>
            <mesh>
              <scale>1 1 1</scale>
              <uri>file:///home/dikki/ros2_ws_simulation/install/gripper_description/share/gripper_description/models/meshes/link2.stl</uri>
            </mesh>
          </geometry>
          <surface>
            <contact>
              <ode/>
            </contact>
            <friction>
              <ode/>
              <torsional>
                <ode/>
              </torsional>
            </friction>
            <bounce/>
          </surface>
          <max_contacts>10</max_contacts>
        </collision>
        <visual name='gripper_soft_robotics_right_finger_link1_visual'>
          <pose>0 0 0 0 -0 0</pose>
          <geometry>
            <mesh>
              <scale>1 1 1</scale>
              <uri>file:///home/dikki/ros2_ws_simulation/install/gripper_description/share/gripper_description/models/meshes/link1.stl</uri>
            </mesh>
          </geometry>
          <material>
            <script>
              <name>Gazebo/Blue</name>
              <uri>file://media/materials/scripts/gazebo.material</uri>
            </script>
          </material>
        </visual>
        <visual name='gripper_soft_robotics_right_finger_link1_fixed_joint_lump__gripper_soft_robotics_right_finger_link2_visual_1'>
          <pose>0 0.009 0.042 0 -0 0</pose>
          <geometry>
            <mesh>
              <scale>1 1 1</scale>
              <uri>file:///home/dikki/ros2_ws_simulation/install/gripper_description/share/gripper_description/models/meshes/link2.stl</uri>
            </mesh>
          </geometry>
          <material>
            <script>
              <name>Gazebo/Blue</name>
              <uri>file://media/materials/scripts/gazebo.material</uri>
            </script>
          </material>
        </visual>
        <self_collide>0</self_collide>
        <enable_wind>0</enable_wind>
        <kinematic>0</kinematic>
      </link>
      <plugin name='camera' filename='librealsense_gazebo_plugin.so'>
        <prefix>realsense</prefix>
        <colorUpdateRate>30</colorUpdateRate>
        <colorTopicName>camera/color/image_raw</colorTopicName>
        <colorOpticalframeName>realsense_color_optical_frame</colorOpticalframeName>
        <colorCameraInfoTopicName>color/camera_info</colorCameraInfoTopicName>
        <infraredUpdateRate>60</infraredUpdateRate>
        <infrared1TopicName>camera/infra1/image_rect_raw</infrared1TopicName>
        <infrared2TopicName>camera/infra2/image_rect_raw</infrared2TopicName>
        <infrared1CameraInfoTopicName>camera/infra1/camera_info</infrared1CameraInfoTopicName>
        <infrared2CameraInfoTopicName>camera/infra2/camera_info</infrared2CameraInfoTopicName>
        <infrared1OpticalframeName>realsense_left_ir_optical_frame</infrared1OpticalframeName>
        <infrared2OpticalframeName>realsense_right_ir_optical_frame</infrared2OpticalframeName>
        <rangeMinDepth>0.2</rangeMinDepth>
        <rangeMaxDepth>10.0</rangeMaxDepth>
        <depthUpdateRate>60</depthUpdateRate>
        <depthTopicName>camera/depth/image_rect_raw</depthTopicName>
        <depthCameraInfoTopicName>camera/depth/camera_info</depthCameraInfoTopicName>
        <depthOpticalframeName>realsense_depth_optical_frame</depthOpticalframeName>
        <pointCloud>1</pointCloud>
        <pointCloudTopicName>depth/color/points</pointCloudTopicName>
        <pointCloudCutoff>0.5</pointCloudCutoff>
      </plugin>
      <static>0</static>
      <plugin name='gazebo_ros2_control' filename='libgazebo_ros2_control.so'>
        <parameters>/home/dikki/ros2_ws_simulation/install/mir_description/share/mir_description/config/diffdrive_controller_combined.yaml</parameters>
      </plugin>
      <pose>0 0 0 0 -0 0</pose>
    </model>
    <!-- REPLACE foldable_chair model with this: -->

    <model name='foldable_chair_with_aruco'>
      <pose>7.75 0.55 0 0 -0 0</pose>
      <static>1</static>
      
      <!-- Chair Base Link -->
      <link name='chair_link'>
        <visual name='visual'>
          <geometry>
            <mesh>
              <scale>0.15 0.15 0.15</scale>
              <uri>/home/dikki/.gazebo/models/foldable_chair/mesh/foldable_chair.dae</uri>
            </mesh>
          </geometry>
        </visual>
        <collision name='collision'>
          <pose>0 0.05 0.4 0 -0 0</pose>
          <geometry>
            <box>
              <size>0.5 0.5 0.8</size>
            </box>
          </geometry>
          <max_contacts>10</max_contacts>
          <surface>
            <contact>
              <ode/>
            </contact>
            <bounce/>
            <friction>
              <torsional>
                <ode/>
              </torsional>
              <ode/>
            </friction>
          </surface>
        </collision>
        <self_collide>0</self_collide>
        <enable_wind>0</enable_wind>
        <kinematic>0</kinematic>
      </link>
      
      <!--  ADD: Aruco Marker Link (marker_1) -->
      <frame name='chair_marker::__model__' attached_to='chair_marker::link'>
        <pose relative_to='__model__'>0 -0.15 0.45 0 -0 4.71239</pose>
      </frame>
      
      <link name='chair_marker::link'>
        <visual name='visual'>
          <geometry>
            <mesh>
              <uri>model://marker_1/meshes/marker_1.dae</uri>
              <scale>1 1 1</scale>
            </mesh>
          </geometry>
        </visual>
        <pose relative_to='chair_marker::__model__'>0 0 0 0 -0 0</pose>
        <self_collide>0</self_collide>
        <inertial>
          <mass>0.001</mass>
          <pose>0 0 0 0 -0 0</pose>
          <inertia>
            <ixx>0.001</ixx>
            <ixy>0</ixy>
            <ixz>0</ixz>
            <iyy>0.001</iyy>
            <iyz>0</iyz>
            <izz>0.001</izz>
          </inertia>
        </inertial>
        <enable_wind>0</enable_wind>
        <kinematic>1</kinematic>
      </link>
      
      <!--  ADD: Fixed Joint (marker attached to chair) -->
      <joint name='marker_joint' type='fixed'>
        <parent>chair_link</parent>
        <child>chair_marker::link</child>
      </joint>
    </model>
    <state world_name='maze_world'>
      <sim_time>87 79000000</sim_time>
      <real_time>89 193728726</real_time>
      <wall_time>1764413703 160981547</wall_time>
      <iterations>87079</iterations>
      <model name='detection_test_box_2'>
        <pose>1.45 -0.139 0.125 0 -0 0</pose>
        <scale>1 1 1</scale>
        <link name='link'>
          <pose>1.45 -0.139 0.125 0 -0 0</pose>
          <velocity>0 0 0 0 -0 0</velocity>
          <acceleration>-0 -0 0 0 -0 0</acceleration>
          <wrench>-0 -0 0 0 -0 0</wrench>
        </link>
      </model>
      <model name='foldable_chair'>
        <pose>7.75363 0.532042 0 0 -0 0</pose>
        <scale>1 1 1</scale>
        <link name='base_link'>
          <pose>7.75363 0.532042 0 0 -0 0</pose>
          <velocity>0 0 0 0 -0 0</velocity>
          <acceleration>0 0 0 0 -0 0</acceleration>
          <wrench>0 0 0 0 -0 0</wrench>
        </link>
      </model>
      <model name='ground_plane'>
        <pose>0 0 0 0 -0 0</pose>
        <scale>1 1 1</scale>
        <link name='link'>
          <pose>0 0 0 0 -0 0</pose>
          <velocity>0 0 0 0 -0 0</velocity>
          <acceleration>0 0 0 0 -0 0</acceleration>
          <wrench>0 0 0 0 -0 0</wrench>
        </link>
      </model>
      <model name='manipulation_test_box_2'>
        <pose>4.64 9.15 0.125 0 -0 0</pose>
        <scale>1 1 1</scale>
        <link name='link'>
          <pose>4.64 9.15 0.125 0 -0 0</pose>
          <velocity>0 0 0 0 -0 0</velocity>
          <acceleration>-0 -0 0 0 -0 0</acceleration>
          <wrench>-0 -0 0 0 -0 0</wrench>
        </link>
      </model>
      <model name='manipulation_test_box_with_aruco'>
        <pose>6.54338 0.499962 0.25 4e-06 -1.4e-05 0</pose>
        <scale>1 1 1</scale>
        <link name='box_link'>
          <pose>6.54338 0.499962 0.25 4e-06 -1.4e-05 0</pose>
          <velocity>0.001447 -0.001786 -0.00147 0.007637 0.003561 0.000537</velocity>
          <acceleration>0.118597 -3.25885 -0.123806 1.46586 0.518017 1.0852</acceleration>
          <wrench>0.023719 -0.65177 -0.024761 0 -0 0</wrench>
        </link>
        <link name='box_marker::link'>
          <pose>6.29339 0.499963 -5e-06 3e-06 -1.7e-05 0</pose>
          <velocity>0.000564 -0.000296 -0.00059 0.006135 0.00354 6.2e-05</velocity>
          <acceleration>0.000766 -0.512306 -0.028908 -1.30364 0.467507 0.11675</acceleration>
          <wrench>0.000766 -0.512306 -0.028908 0 -0 0</wrench>
        </link>
      </model>
      <model name='maze'>
        <pose>-0.078283 0.098984 0 0 -0 0</pose>
        <scale>1 1 1</scale>
        <link name='Wall_0'>
          <pose>-0.047747 10.024 0 0 -0 0</pose>
          <velocity>0 0 0 0 -0 0</velocity>
          <acceleration>0 0 0 0 -0 0</acceleration>
          <wrench>0 0 0 0 -0 0</wrench>
        </link>
        <link name='Wall_1'>
          <pose>9.87726 0.098984 0 0 0 -1.5708</pose>
          <velocity>0 0 0 0 -0 0</velocity>
          <acceleration>0 0 0 0 -0 0</acceleration>
          <wrench>0 0 0 0 -0 0</wrench>
        </link>
        <link name='Wall_2'>
          <pose>-0.047747 -9.82602 0 0 -0 3.14159</pose>
          <velocity>0 0 0 0 -0 0</velocity>
          <acceleration>0 0 0 0 -0 0</acceleration>
          <wrench>0 0 0 0 -0 0</wrench>
        </link>
        <link name='Wall_24'>
          <pose>5.27261 3.31804 0 0 -0 3.14159</pose>
          <velocity>0 0 0 0 -0 0</velocity>
          <acceleration>0 0 0 0 -0 0</acceleration>
          <wrench>0 0 0 0 -0 0</wrench>
        </link>
        <link name='Wall_25'>
          <pose>4.59761 5.86804 0 0 -0 1.5708</pose>
          <velocity>0 0 0 0 -0 0</velocity>
          <acceleration>0 0 0 0 -0 0</acceleration>
          <wrench>0 0 0 0 -0 0</wrench>
        </link>
        <link name='Wall_27'>
          <pose>7.03086 4.83352 0 0 0 -1.5708</pose>
          <velocity>0 0 0 0 -0 0</velocity>
          <acceleration>0 0 0 0 -0 0</acceleration>
          <wrench>0 0 0 0 -0 0</wrench>
        </link>
        <link name='Wall_28'>
          <pose>8.45586 2.15852 0 0 -0 0</pose>
          <velocity>0 0 0 0 -0 0</velocity>
          <acceleration>0 0 0 0 -0 0</acceleration>
          <wrench>0 0 0 0 -0 0</wrench>
        </link>
        <link name='Wall_3'>
          <pose>-9.97274 0.098984 0 0 -0 1.5708</pose>
          <velocity>0 0 0 0 -0 0</velocity>
          <acceleration>0 0 0 0 -0 0</acceleration>
          <wrench>0 0 0 0 -0 0</wrench>
        </link>
        <link name='Wall_30'>
          <pose>-4.43742 -2.72991 0 0 0 -1.5708</pose>
          <velocity>0 0 0 0 -0 0</velocity>
          <acceleration>0 0 0 0 -0 0</acceleration>
          <wrench>0 0 0 0 -0 0</wrench>
        </link>
        <link name='Wall_31'>
          <pose>-7.23742 -5.40491 0 0 -0 3.14159</pose>
          <velocity>0 0 0 0 -0 0</velocity>
          <acceleration>0 0 0 0 -0 0</acceleration>
          <wrench>0 0 0 0 -0 0</wrench>
        </link>
        <link name='Wall_5'>
          <pose>-1.97739 1.96804 0 0 -0 0</pose>
          <velocity>0 0 0 0 -0 0</velocity>
          <acceleration>0 0 0 0 -0 0</acceleration>
          <wrench>0 0 0 0 -0 0</wrench>
        </link>
        <link name='Wall_6'>
          <pose>5.94761 2.64304 0 0 -0 1.5708</pose>
          <velocity>0 0 0 0 -0 0</velocity>
          <acceleration>0 0 0 0 -0 0</acceleration>
          <wrench>0 0 0 0 -0 0</wrench>
        </link>
        <link name='Wall_8'>
          <pose>5.94761 3.31804 0 0 -0 0</pose>
          <velocity>0 0 0 0 -0 0</velocity>
          <acceleration>0 0 0 0 -0 0</acceleration>
          <wrench>0 0 0 0 -0 0</wrench>
        </link>
      </model>
      <model name='mir_robot'>
        <pose>-0.033131 -0.018878 -4.3e-05 -1.2e-05 -5.6e-05 0.005804</pose>
        <scale>1 1 1</scale>
        <link name='base_footprint'>
          <pose>-0.033131 -0.018878 -4.3e-05 -1.2e-05 -5.6e-05 0.005804</pose>
          <velocity>-0.000466 -0.000434 -0.00066 -0.004048 0.000742 0.000271</velocity>
          <acceleration>-0.002144 0.096074 1.41352 -2.78829 -1.1544 -1.75708</acceleration>
          <wrench>-0.574457 25.7381 378.683 0 -0 0</wrench>
        </link>
        <link name='bl_caster_rotation_link'>
          <pose>-0.330227 0.167404 0.156477 -0.0001 0.000817 -0.80451</pose>
          <velocity>-0.000651 1.3e-05 -0.000446 -0.001002 0.020086 -0.072098</velocity>
          <acceleration>1.04287 -1.58713 1.33024 0.641031 -1.39419 -0.045221</acceleration>
          <wrench>0.323032 -0.49162 0.412049 0 -0 0</wrench>
        </link>
        <link name='bl_caster_wheel_link'>
          <pose>-0.356741 0.194937 0.0625 -0.000108 -0.394251 -0.804467</pose>
          <velocity>0.00031 0.001171 -0.000111 -0.012754 0.010716 -0.070414</velocity>
          <acceleration>0.494508 -0.522547 -0.199817 0.076724 -0.149101 2.34095</acceleration>
          <wrench>0.494508 -0.522547 -0.199817 0 -0 0</wrench>
        </link>
        <link name='br_caster_rotation_link'>
          <pose>-0.328045 -0.20859 0.156479 -9.4e-05 0.000757 -0.795418</pose>
          <velocity>-0.000309 -4.4e-05 0.000268 -0.009046 0.001546 -0.035372</velocity>
          <acceleration>-1.04851 1.35054 -1.22629 -2.74164 1.33854 2.44503</acceleration>
          <wrench>-0.324781 0.418334 -0.379849 0 -0 0</wrench>
        </link>
        <link name='br_caster_wheel_link'>
          <pose>-0.354806 -0.1813 0.0625 -0.0001 -0.363354 -0.795381</pose>
          <velocity>0.000531 0.000187 7.7e-05 -0.007017 0.004544 -0.034501</velocity>
          <acceleration>-1.21504 1.36071 0.068709 2.01232 1.52073 1.67362</acceleration>
          <wrench>-1.21504 1.36071 0.068709 0 -0 0</wrench>
        </link>
        <link name='fl_caster_rotation_link'>
          <pose>0.269463 0.170884 0.15649 -3.6e-05 0.000358 -0.648742</pose>
          <velocity>-0.000709 0.00011 -0.000642 -0.002664 0.025924 -0.079396</velocity>
          <acceleration>1.797 -1.14254 1.86286 0.625916 -0.212938 -2.91944</acceleration>
          <wrench>0.556628 -0.353906 0.577027 0 -0 0</wrench>
        </link>
        <link name='fl_caster_wheel_link'>
          <pose>0.239014 0.193966 0.0625 -4e-05 -0.447106 -0.648723</pose>
          <velocity>-3.7e-05 0.001553 -0.000144 -0.016873 0.009928 -0.07728</velocity>
          <acceleration>0.864556 -0.474693 -0.237675 1.04473 0.973649 2.45092</acceleration>
          <wrench>0.864556 -0.474693 -0.237675 0 -0 0</wrench>
        </link>
        <link name='fr_caster_rotation_link'>
          <pose>0.271645 -0.20511 0.156492 -3.1e-05 0.000297 -0.643403</pose>
          <velocity>-0.000383 7.3e-05 7e-05 -0.00897 0.007354 -0.049871</velocity>
          <acceleration>-0.747491 1.34039 -0.687857 0.803984 0.36822 0.346762</acceleration>
          <wrench>-0.231538 0.415191 -0.213066 0 -0 0</wrench>
        </link>
        <link name='fr_caster_wheel_link'>
          <pose>0.241076 -0.182191 0.0625 -3.5e-05 -0.414421 -0.643386</pose>
          <velocity>0.000392 0.000698 4.5e-05 -0.011587 0.005716 -0.048403</velocity>
          <acceleration>-1.05381 1.06902 0.032565 -0.107525 -0.275366 -1.8878</acceleration>
          <wrench>-1.05381 1.06902 0.032565 0 -0 0</wrench>
        </link>
        <link name='gripper_soft_robotics_left_finger_link1'>
          <pose>0.705811 -0.175473 1.39019 -3.12848 1.22085 -3.1228</pose>
          <velocity>0.004244 0.027768 -0.010214 -0.030286 0.023514 0.000872</velocity>
          <acceleration>1.24135 0.401726 -10.0714 1.31247 1.26251 -0.9349</acceleration>
          <wrench>0.417093 0.13498 -3.384 0 -0 0</wrench>
        </link>
        <link name='gripper_soft_robotics_right_finger_link1'>
          <pose>0.705254 -0.119476 1.39001 3.12723 -1.22084 0.018814</pose>
          <velocity>0.002236 0.027989 -0.011143 -0.031935 0.02309 -0.004573</velocity>
          <acceleration>-0.831913 0.51353 -9.5996 -1.34435 0.504614 -1.71842</acceleration>
          <wrench>-0.279523 0.172546 -3.22546 0 -0 0</wrench>
        </link>
        <link name='left_wheel_link'>
          <pose>-0.034306 0.182616 0.099989 3.4e-05 -0.308201 0.005794</pose>
          <velocity>-0.000438 -0.000955 0.002115 0.010473 -0.004427 0.000257</velocity>
          <acceleration>-0.097096 0.893604 8.96258 2.29222 -0.832 1.3719</acceleration>
          <wrench>-0.097096 0.893604 8.96258 0 -0 0</wrench>
        </link>
        <link name='right_wheel_link'>
          <pose>-0.031967 -0.220365 0.100003 0.000131 -0.299869 0.005765</pose>
          <velocity>-0.000352 0.00078 0.001151 -0.009489 -0.003492 0.000211</velocity>
          <acceleration>0.438481 2.63068 -1.37373 1.18478 0.047808 1.32613</acceleration>
          <wrench>0.438481 2.63068 -1.37373 0 -0 0</wrench>
        </link>
        <link name='ur_forearm_link'>
          <pose>0.100647 -0.018089 1.37746 -1.57079 -0.04084 -3.13607</pose>
          <velocity>0.001038 0.012158 -0.000692 -0.019555 0.019724 0.017521</velocity>
          <acceleration>-1.64852 -11.0258 -2.33706 1.16808 -1.40819 -3.00602</acceleration>
          <wrench>-0.329704 -2.20516 -0.467412 0 -0 0</wrench>
        </link>
        <link name='ur_shoulder_link'>
          <pose>0.101814 -0.018084 0.952464 -1.3e-05 -5.6e-05 0.005518</pose>
          <velocity>0.000285 0.00267 -0.000736 0.002094 0.000744 0.017454</velocity>
          <acceleration>-1.43304 -14.5207 1.7697 -2.91285 -1.09436 2.84881</acceleration>
          <wrench>-0.286608 -2.90415 0.35394 0 -0 0</wrench>
        </link>
        <link name='ur_upper_arm_link'>
          <pose>0.101814 -0.018084 0.952463 1.5692 1.56805 0.003921</pose>
          <velocity>0.00028 0.003292 -0.000698 -0.019511 0.001858 0.017339</velocity>
          <acceleration>0.36978 -15.3468 1.43047 -0.964317 -0.939384 -0.990538</acceleration>
          <wrench>0.073956 -3.06936 0.286094 0 -0 0</wrench>
        </link>
        <link name='ur_wrist_1_link'>
          <pose>0.493249 -0.149225 1.36145 -1.57079 -0.349937 -3.13608</pose>
          <velocity>0.00294 0.019137 -0.005846 -0.020418 0.02235 0.017066</velocity>
          <acceleration>0.409677 -7.72761 -5.35931 -1.4646 -0.547922 0.332534</acceleration>
          <wrench>0.081935 -1.54552 -1.07186 0 -0 0</wrench>
        </link>
        <link name='ur_wrist_2_link'>
          <pose>0.52743 -0.149036 1.4551 -0.349936 0.001042 -1.56241</pose>
          <velocity>0.004884 0.022099 -0.00658 -0.015986 0.021982 0.037817</velocity>
          <acceleration>1.68129 -6.33861 -6.17107 1.13057 0.538288 0.642464</acceleration>
          <wrench>0.336258 -1.26772 -1.23422 0 -0 0</wrench>
        </link>
        <link name='ur_wrist_3_link'>
          <pose>0.62099 -0.148216 1.42096 -1.92074 -0.003232 -1.56085</pose>
          <velocity>0.004043 0.025323 -0.008693 -0.015981 0.023211 0.038605</velocity>
          <acceleration>1.14076 -2.60078 -7.85909 3.01873 -0.228559 -2.76918</acceleration>
          <wrench>0.501935 -1.14434 -3.458 0 -0 0</wrench>
        </link>
      </model>
      <light name='sun'>
        <pose>0 0 10 0 -0 0</pose>
      </light>
    </state>
    <gui fullscreen='0'>
      <camera name='user_camera'>
        <pose>6.36151 -5.89478 5.30749 0 0.611643 1.56819</pose>
        <view_controller>orbit</view_controller>
        <projection_type>perspective</projection_type>
      </camera>
    </gui>
  </world>
</sdf>